Workbook

Sheet RANKING
A1: ⚽ PORRA MUNDIAL 2026 — RANKING FASE DE GRUPOS
A2: Actualiza introduciendo los resultados reales (celdas amarillas) en cada hoja de grupo
A3: POS | B3: PARTICIPANTE | C3: PUNTOS TOTALES
A4: 1 | B4: Aaron | C4: ='Grupo A'!F21+'Grupo B'!F21+'Grupo C'!F21+'Grupo D'!F21+'Grupo E'!F21+'Grupo F'!F21+'Grupo G'!F21+'Grupo H'!F21+'Grupo I'!F21+'Grupo J'!F21+'Grupo K'!F21+'Grupo L'!F21 -> 0
A5: 2 | B5: Aitor | C5: ='Grupo A'!I21+'Grupo B'!I21+'Grupo C'!I21+'Grupo D'!I21+'Grupo E'!I21+'Grupo F'!I21+'Grupo G'!I21+'Grupo H'!I21+'Grupo I'!I21+'Grupo J'!I21+'Grupo K'!I21+'Grupo L'!I21 -> 0
A6: 3 | B6: Coco | C6: ='Grupo A'!L21+'Grupo B'!L21+'Grupo C'!L21+'Grupo D'!L21+'Grupo E'!L21+'Grupo F'!L21+'Grupo G'!L21+'Grupo H'!L21+'Grupo I'!L21+'Grupo J'!L21+'Grupo K'!L21+'Grupo L'!L21 -> 0
A7: 4 | B7: Danel | C7: ='Grupo A'!O21+'Grupo B'!O21+'Grupo C'!O21+'Grupo D'!O21+'Grupo E'!O21+'Grupo F'!O21+'Grupo G'!O21+'Grupo H'!O21+'Grupo I'!O21+'Grupo J'!O21+'Grupo K'!O21+'Grupo L'!O21 -> 0
A8: 5 | B8: Guille | C8: ='Grupo A'!R21+'Grupo B'!R21+'Grupo C'!R21+'Grupo D'!R21+'Grupo E'!R21+'Grupo F'!R21+'Grupo G'!R21+'Grupo H'!R21+'Grupo I'!R21+'Grupo J'!R21+'Grupo K'!R21+'Grupo L'!R21 -> 0
A9: 6 | B9: Jaime | C9: ='Grupo A'!U21+'Grupo B'!U21+'Grupo C'!U21+'Grupo D'!U21+'Grupo E'!U21+'Grupo F'!U21+'Grupo G'!U21+'Grupo H'!U21+'Grupo I'!U21+'Grupo J'!U21+'Grupo K'!U21+'Grupo L'!U21 -> 0
A10: 7 | B10: JonBel | C10: ='Grupo A'!X21+'Grupo B'!X21+'Grupo C'!X21+'Grupo D'!X21+'Grupo E'!X21+'Grupo F'!X21+'Grupo G'!X21+'Grupo H'!X21+'Grupo I'!X21+'Grupo J'!X21+'Grupo K'!X21+'Grupo L'!X21 -> 0
A11: 8 | B11: JonMo | C11: ='Grupo A'!AA21+'Grupo B'!AA21+'Grupo C'!AA21+'Grupo D'!AA21+'Grupo E'!AA21+'Grupo F'!AA21+'Grupo G'!AA21+'Grupo H'!AA21+'Grupo I'!AA21+'Grupo J'!AA21+'Grupo K'!AA21+'Grupo L'!AA21 -> 0
A12: 9 | B12: JuanLu | C12: ='Grupo A'!AD21+'Grupo B'!AD21+'Grupo C'!AD21+'Grupo D'!AD21+'Grupo E'!AD21+'Grupo F'!AD21+'Grupo G'!AD21+'Grupo H'!AD21+'Grupo I'!AD21+'Grupo J'!AD21+'Grupo K'!AD21+'Grupo L'!AD21 -> 0
A13: 10 | B13: JuanRo | C13: ='Grupo A'!AG21+'Grupo B'!AG21+'Grupo C'!AG21+'Grupo D'!AG21+'Grupo E'!AG21+'Grupo F'!AG21+'Grupo G'!AG21+'Grupo H'!AG21+'Grupo I'!AG21+'Grupo J'!AG21+'Grupo K'!AG21+'Grupo L'!AG21 -> 0
A14: 11 | B14: LuisMi | C14: ='Grupo A'!AJ21+'Grupo B'!AJ21+'Grupo C'!AJ21+'Grupo D'!AJ21+'Grupo E'!AJ21+'Grupo F'!AJ21+'Grupo G'!AJ21+'Grupo H'!AJ21+'Grupo I'!AJ21+'Grupo J'!AJ21+'Grupo K'!AJ21+'Grupo L'!AJ21 -> 0
A15: 12 | B15: Mario | C15: ='Grupo A'!AM21+'Grupo B'!AM21+'Grupo C'!AM21+'Grupo D'!AM21+'Grupo E'!AM21+'Grupo F'!AM21+'Grupo G'!AM21+'Grupo H'!AM21+'Grupo I'!AM21+'Grupo J'!AM21+'Grupo K'!AM21+'Grupo L'!AM21 -> 0
A16: 13 | B16: Pablo | C16: ='Grupo A'!AP21+'Grupo B'!AP21+'Grupo C'!AP21+'Grupo D'!AP21+'Grupo E'!AP21+'Grupo F'!AP21+'Grupo G'!AP21+'Grupo H'!AP21+'Grupo I'!AP21+'Grupo J'!AP21+'Grupo K'!AP21+'Grupo L'!AP21 -> 0
A17: 14 | B17: Roberto | C17: ='Grupo A'!AS21+'Grupo B'!AS21+'Grupo C'!AS21+'Grupo D'!AS21+'Grupo E'!AS21+'Grupo F'!AS21+'Grupo G'!AS21+'Grupo H'!AS21+'Grupo I'!AS21+'Grupo J'!AS21+'Grupo K'!AS21+'Grupo L'!AS21 -> 0
A18: 15 | B18: Txiki | C18: ='Grupo A'!AV21+'Grupo B'!AV21+'Grupo C'!AV21+'Grupo D'!AV21+'Grupo E'!AV21+'Grupo F'!AV21+'Grupo G'!AV21+'Grupo H'!AV21+'Grupo I'!AV21+'Grupo J'!AV21+'Grupo K'!AV21+'Grupo L'!AV21 -> 0
A19: 16 | B19: Wiki | C19: ='Grupo A'!AY21+'Grupo B'!AY21+'Grupo C'!AY21+'Grupo D'!AY21+'Grupo E'!AY21+'Grupo F'!AY21+'Grupo G'!AY21+'Grupo H'!AY21+'Grupo I'!AY21+'Grupo J'!AY21+'Grupo K'!AY21+'Grupo L'!AY21 -> 0
A20: 17 | B20: Xabi | C20: ='Grupo A'!BB21+'Grupo B'!BB21+'Grupo C'!BB21+'Grupo D'!BB21+'Grupo E'!BB21+'Grupo F'!BB21+'Grupo G'!BB21+'Grupo H'!BB21+'Grupo I'!BB21+'Grupo J'!BB21+'Grupo K'!BB21+'Grupo L'!BB21 -> 0

Sheet Grupo A
A1: ⚽ GRUPO A — México · Sudáfrica · Corea del Sur · Rep. Checa
A2: JOR. | B2: LOCAL | C2: VS | D2: VISITANTE | E2: FECHA | F2: Aaron | I2: Aitor | L2: Coco | O2: Danel | R2: Guille | U2: Jaime | X2: JonBel | AA2: JonMo | AD2: JuanLu | AG2: JuanRo | AJ2: LuisMi | AM2: Mario | AP2: Pablo | AS2: Roberto | AV2: Txiki | AY2: Wiki | BB2: Xabi | BE2: ✅ RESULTADO REAL
F3: L | G3: V | H3: ± | I3: L | J3: V | K3: ± | L3: L | M3: V | N3: ± | O3: L | P3: V | Q3: ± | R3: L | S3: V | T3: ± | U3: L | V3: V | W3: ± | X3: L | Y3: V | Z3: ± | AA3: L | AB3: V | AC3: ± | AD3: L | AE3: V | AF3: ± | AG3: L | AH3: V | AI3: ± | AJ3: L | AK3: V | AL3: ± | AM3: L | AN3: V | AO3: ± | AP3: L | AQ3: V | AR3: ± | AS3: L | AT3: V | AU3: ± | AV3: L | AW3: V | AX3: ± | AY3: L | AZ3: V | BA3: ± | BB3: L | BC3: V | BD3: ± | BE3: GOL L | BF3: GOL V
A4: 1 | B4: México | C4: vs | D4: Sudáfrica | F4: 3 | G4: 1 | H4: 1 | L4: 3 | M4: 1 | N4: 1 | O4: 2 | P4: 0 | Q4: 1 | R4: 3 | S4: 1 | T4: 1 | U4: 3 | V4: 0 | W4: 1 | X4: 2 | Y4: 1 | Z4: 1 | AA4: 2 | AB4: 0 | AC4: 1 | AD4: 1 | AE4: 0 | AF4: X | AG4: 3 | AH4: 1 | AI4: 1 | AM4: 2 | AN4: 0 | AO4: 1 | AP4: 2 | AQ4: 0 | AR4: 1 | AS4: 1 | AT4: 1 | AU4: X | AV4: 2 | AW4: 1 | AX4: 1 | AY4: 2 | AZ4: 0 | BA4: 1 | BB4: 2 | BC4: 0 | BD4: 1
A5: 1 | B5: Corea del Sur | C5: vs | D5: Rep. Checa | F5: 1 | G5: 1 | H5: X | L5: 1 | M5: 1 | N5: 1 | O5: 1 | P5: 1 | Q5: X | R5: 2 | S5: 1 | T5: 1 | U5: 2 | V5: 2 | W5: X | X5: 1 | Y5: 1 | Z5: 1 | AA5: 1 | AB5: 1 | AC5: X | AD5: 1 | AE5: 1 | AF5: 2 | AG5: 1 | AH5: 1 | AI5: X | AM5: 1 | AN5: 1 | AO5: X | AP5: 1 | AQ5: 1 | AR5: 2 | AS5: 1 | AT5: 3 | AU5: 2 | AV5: 1 | AW5: 1 | AX5: X | AY5: 1 | AZ5: 1 | BA5: 2 | BB5: 1 | BC5: 1 | BD5: X
A6: 2 | B6: México | C6: vs | D6: Corea del Sur | F6: 2 | G6: 0 | H6: 1 | L6: 2 | M6: 2 | N6: 1 | O6: 1 | P6: 0 | Q6: 1 | R6: 2 | S6: 0 | T6: 1 | U6: 2 | V6: 1 | W6: 1 | X6: 3 | Y6: 2 | Z6: X | AA6: 1 | AB6: 1 | AC6: X | AD6: 1 | AE6: 1 | AF6: 2 | AG6: 1 | AH6: 2 | AI6: X | AM6: 2 | AN6: 1 | AO6: 1 | AP6: 1 | AQ6: 1 | AR6: 1 | AS6: 2 | AT6: 0 | AU6: 1 | AV6: 2 | AW6: 1 | AX6: 1 | AY6: 1 | AZ6: 1 | BA6: 1 | BB6: 1 | BC6: 1 | BD6: X
A7: 2 | B7: Sudáfrica | C7: vs | D7: Rep. Checa | F7: 1 | G7: 1 | H7: X | L7: 0 | M7: 3 | N7: 2 | O7: 1 | P7: 2 | Q7: 2 | R7: 2 | S7: 2 | T7: 2 | U7: 1 | V7: 3 | W7: 2 | X7: 0 | Y7: 1 | Z7: 2 | AA7: 0 | AB7: 2 | AC7: 2 | AD7: 0 | AE7: 2 | AF7: X | AG7: 1 | AH7: 2 | AI7: 2 | AM7: 0 | AN7: 1 | AO7: 2 | AP7: 0 | AQ7: 2 | AR7: 2 | AS7: 1 | AT7: 2 | AU7: 2 | AV7: 1 | AW7: 2 | AX7: 2 | AY7: 1 | AZ7: 0 | BA7: 2 | BB7: 0 | BC7: 1 | BD7: 2
A8: 3 | B8: Rep. Checa | C8: vs | D8: México | F8: 0 | G8: 1 | H8: 2 | L8: 0 | M8: 2 | N8: X | O8: 0 | P8: 2 | Q8: 2 | R8: 1 | S8: 2 | T8: 1 | U8: 1 | V8: 1 | W8: X | X8: 1 | Y8: 1 | Z8: 2 | AA8: 1 | AB8: 2 | AC8: 2 | AD8: 2 | AE8: 2 | AF8: 1 | AG8: 1 | AH8: 1 | AI8: X | AM8: 1 | AN8: 2 | AO8: 2 | AP8: 0 | AQ8: 1 | AR8: 2 | AS8: 2 | AT8: 2 | AU8: X | AV8: 1 | AW8: 1 | AX8: X | AY8: 1 | AZ8: 3 | BA8: 2 | BB8: 2 | BC8: 1 | BD8: 1
A9: 3 | B9: Sudáfrica | C9: vs | D9: Corea del Sur | F9: 0 | G9: 2 | H9: 2 | L9: 1 | M9: 3 | N9: 2 | O9: 1 | P9: 1 | Q9: X | R9: 3 | S9: 1 | T9: 1 | U9: 0 | V9: 2 | W9: 2 | X9: 0 | Y9: 2 | Z9: 2 | AA9: 0 | AB9: 1 | AC9: 2 | AD9: 0 | AE9: 1 | AF9: X | AG9: 1 | AH9: 2 | AI9: 2 | AM9: 1 | AN9: 2 | AO9: 2 | AP9: 0 | AQ9: 1 | AR9: X | AS9: 2 | AT9: 0 | AU9: 1 | AV9: 1 | AW9: 1 | AX9: X | AY9: 2 | AZ9: 2 | BA9: 1 | BB9: 1 | BC9: 1 | BD9: X
A11: 📊 CLASIFICACIÓN DEL GRUPO (rellena los equipos reales en amarillo)
A12: 🥇 1º | F12: México | L12: México | O12: México | R12: México | U12: México | X12: Mexico | AA12: México | AD12: REPUBLICA CHECA | AG12: COREA DEL SUR | AM12: Mexico | AP12: México | AS12: Re. Checa | AV12: mexico | AY12: Mexico | BB12: Rep. Checa
A13: 🥈 2º | F13: Corea del Sur | L13: Corea del Sur | O13: Corea del Sur | R13: Corea del Sur | U13: Rep. Checa | X13: Corea del Sur | AA13: Corea del Sur | AD13: MÉXICO | AG13: MÉXICO | AM13: Chequia | AP13: Rep. Checa | AS13: Mexico | AV13: republica checa | AY13: Rep. Checa | BB13: Mexico
A14: 🥉 3º | F14: Rep. Checa | L14: República Checa | O14: Rep. Checa | R14: Sudáfrica | U14: Corea del Sur | X14: Rep. Checa | AA14: Rep. Checa | AD14: COREA DEL SUR | AG14: REP.CHECA | AM14: Corea | AP14: Corea del Sur | AS14: Sudafrica | AV14: corea del sur | AY14: Corea del Sur | BB14: Corea del sur
A16: 🎯 PUNTOS TOTALES
A17: Signos acertados (1 pt c/u) | F17: =IF(AND(BE4<>"",BF4<>""),IF(IF(BE4>BF4,"1",IF(BE4<BF4,"2","X"))="1",1,0),0)+IF(AND(BE5<>"",BF5<>""),IF(IF(BE5>BF5,"1",IF(BE5<BF5,"2","X"))="X",1,0),0)+IF(AND(BE6<>"",BF6<>""),IF(IF(BE6>BF6,"1",IF(BE6<BF6,"2","X"))="1",1,0),0)+IF(AND(BE7<>"",BF7<>""),IF(IF(BE7>BF7,"1",IF(BE7<BF7,"2","X"))="X",1,0),0)+IF(AND(BE8<>"",BF8<>""),IF(IF(BE8>BF8,"1",IF(BE8<BF8,"2","X"))="2",1,0),0)+IF(AND(BE9<>"",BF9<>""),IF(IF(BE9>BF9,"1",IF(BE9<BF9,"2","X"))="2",1,0),0) -> 0 | I17: =0+0+0+0+0+0 -> 0 | L17: =IF(AND(BE4<>"",BF4<>""),IF(IF(BE4>BF4,"1",IF(BE4<BF4,"2","X"))="1",1,0),0)+IF(AND(BE5<>"",BF5<>""),IF(IF(BE5>BF5,"1",IF(BE5<BF5,"2","X"))="1",1,0),0)+IF(AND(BE6<>"",BF6<>""),IF(IF(BE6>BF6,"1",IF(BE6<BF6,"2","X"))="1",1,0),0)+IF(AND(BE7<>"",BF7<>""),IF(IF(BE7>BF7,"1",IF(BE7<BF7,"2","X"))="2",1,0),0)+IF(AND(BE8<>"",BF8<>""),IF(IF(BE8>BF8,"1",IF(BE8<BF8,"2","X"))="X",1,0),0)+IF(AND(BE9<>"",BF9<>""),IF(IF(BE9>BF9,"1",IF(BE9<BF9,"2","X"))="2",1,0),0) -> 0 | O17: =IF(AND(BE4<>"",BF4<>""),IF(IF(BE4>BF4,"1",IF(BE4<BF4,"2","X"))="1",1,0),0)+IF(AND(BE5<>"",BF5<>""),IF(IF(BE5>BF5,"1",IF(BE5<BF5,"2","X"))="X",1,0),0)+IF(AND(BE6<>"",BF6<>""),IF(IF(BE6>BF6,"1",IF(BE6<BF6,"2","X"))="1",1,0),0)+IF(AND(BE7<>"",BF7<>""),IF(IF(BE7>BF7,"1",IF(BE7<BF7,"2","X"))="2",1,0),0)+IF(AND(BE8<>"",BF8<>""),IF(IF(BE8>BF8,"1",IF(BE8<BF8,"2","X"))="2",1,0),0)+IF(AND(BE9<>"",BF9<>""),IF(IF(BE9>BF9,"1",IF(BE9<BF9,"2","X"))="X",1,0),0) -> 0 | R17: =IF(AND(BE4<>"",BF4<>""),IF(IF(BE4>BF4,"1",IF(BE4<BF4,"2","X"))="1",1,0),0)+IF(AND(BE5<>"",BF5<>""),IF(IF(BE5>BF5,"1",IF(BE5<BF5,"2","X"))="1",1,0),0)+IF(AND(BE6<>"",BF6<>""),IF(IF(BE6>BF6,"1",IF(BE6<BF6,"2","X"))="1",1,0),0)+IF(AND(BE7<>"",BF7<>""),IF(IF(BE7>BF7,"1",IF(BE7<BF7,"2","X"))="2",1,0),0)+IF(AND(BE8<>"",BF8<>""),IF(IF(BE8>BF8,"1",IF(BE8<BF8,"2","X"))="1",1,0),0)+IF(AND(BE9<>"",BF9<>""),IF(IF(BE9>BF9,"1",IF(BE9<BF9,"2","X"))="1",1,0),0) -> 0 | U17: =IF(AND(BE4<>"",BF4<>""),IF(IF(BE4>BF4,"1",IF(BE4<BF4,"2","X"))="1",1,0),0)+IF(AND(BE5<>"",BF5<>""),IF(IF(BE5>BF5,"1",IF(BE5<BF5,"2","X"))="X",1,0),0)+IF(AND(BE6<>"",BF6<>""),IF(IF(BE6>BF6,"1",IF(BE6<BF6,"2","X"))="1",1,0),0)+IF(AND(BE7<>"",BF7<>""),IF(IF(BE7>BF7,"1",IF(BE7<BF7,"2","X"))="2",1,0),0)+IF(AND(BE8<>"",BF8<>""),IF(IF(BE8>BF8,"1",IF(BE8<BF8,"2","X"))="X",1,0),0)+IF(AND(BE9<>"",BF9<>""),IF(IF(BE9>BF9,"1",IF(BE9<BF9,"2","X"))="2",1,0),0) -> 0 | X17: =IF(AND(BE4<>"",BF4<>""),IF(IF(BE4>BF4,"1",IF(BE4<BF4,"2","X"))="1",1,0),0)+IF(AND(BE5<>"",BF5<>""),IF(IF(BE5>BF5,"1",IF(BE5<BF5,"2","X"))="1",1,0),0)+IF(AND(BE6<>"",BF6<>""),IF(IF(BE6>BF6,"1",IF(BE6<BF6,"2","X"))="X",1,0),0)+IF(AND(BE7<>"",BF7<>""),IF(IF(BE7>BF7,"1",IF(BE7<BF7,"2","X"))="2",1,0),0)+IF(AND(BE8<>"",BF8<>""),IF(IF(BE8>BF8,"1",IF(BE8<BF8,"2","X"))="2",1,0),0)+IF(AND(BE9<>"",BF9<>""),IF(IF(BE9>BF9,"1",IF(BE9<BF9,"2","X"))="2",1,0),0) -> 0 | AA17: =IF(AND(BE4<>"",BF4<>""),IF(IF(BE4>BF4,"1",IF(BE4<BF4,"2","X"))="1",1,0),0)+IF(AND(BE5<>"",BF5<>""),IF(IF(BE5>BF5,"1",IF(BE5<BF5,"2","X"))="X",1,0),0)+IF(AND(BE6<>"",BF6<>""),IF(IF(BE6>BF6,"1",IF(BE6<BF6,"2","X"))="X",1,0),0)+IF(AND(BE7<>"",BF7<>""),IF(IF(BE7>BF7,"1",IF(BE7<BF7,"2","X"))="2",1,0),0)+IF(AND(BE8<>"",BF8<>""),IF(IF(BE8>BF8,"1",IF(BE8<BF8,"2","X"))="2",1,0),0)+IF(AND(BE9<>"",BF9<>""),IF(IF(BE9>BF9,"1",IF(BE9<BF9,"2","X"))="2",1,0),0) -> 0 | AD17: =IF(AND(BE4<>"",BF4<>""),IF(IF(BE4>BF4,"1",IF(BE4<BF4,"2","X"))="X",1,0),0)+IF(AND(BE5<>"",BF5<>""),IF(IF(BE5>BF5,"1",IF(BE5<BF5,"2","X"))="2",1,0),0)+IF(AND(BE6<>"",BF6<>""),IF(IF(BE6>BF6,"1",IF(BE6<BF6,"2","X"))="2",1,0),0)+IF(AND(BE7<>"",BF7<>""),IF(IF(BE7>BF7,"1",IF(BE7<BF7,"2","X"))="X",1,0),0)+IF(AND(BE8<>"",BF8<>""),IF(IF(BE8>BF8,"1",IF(BE8<BF8,"2","X"))="1",1,0),0)+IF(AND(BE9<>"",BF9<>""),IF(IF(BE9>BF9,"1",IF(BE9<BF9,"2","X"))="X",1,0),0) -> 0 | AG17: =IF(AND(BE4<>"",BF4<>""),IF(IF(BE4>BF4,"1",IF(BE4<BF4,"2","X"))="1",1,0),0)+IF(AND(BE5<>"",BF5<>""),IF(IF(BE5>BF5,"1",IF(BE5<BF5,"2","X"))="X",1,0),0)+IF(AND(BE6<>"",BF6<>""),IF(IF(BE6>BF6,"1",IF(BE6<BF6,"2","X"))="X",1,0),0)+IF(AND(BE7<>"",BF7<>""),IF(IF(BE7>BF7,"1",IF(BE7<BF7,"2","X"))="2",1,0),0)+IF(AND(BE8<>"",BF8<>""),IF(IF(BE8>BF8,"1",IF(BE8<BF8,"2","X"))="X",1,0),0)+IF(AND(BE9<>"",BF9<>""),IF(IF(BE9>BF9,"1",IF(BE9<BF9,"2","X"))="2",1,0),0) -> 0 | AJ17: =0+0+0+0+0+0 -> 0 | AM17: =IF(AND(BE4<>"",BF4<>""),IF(IF(BE4>BF4,"1",IF(BE4<BF4,"2","X"))="1",1,0),0)+IF(AND(BE5<>"",BF5<>""),IF(IF(BE5>BF5,"1",IF(BE5<BF5,"2","X"))="X",1,0),0)+IF(AND(BE6<>"",BF6<>""),IF(IF(BE6>BF6,"1",IF(BE6<BF6,"2","X"))="1",1,0),0)+IF(AND(BE7<>"",BF7<>""),IF(IF(BE7>BF7,"1",IF(BE7<BF7,"2","X"))="2",1,0),0)+IF(AND(BE8<>"",BF8<>""),IF(IF(BE8>BF8,"1",IF(BE8<BF8,"2","X"))="2",1,0),0)+IF(AND(BE9<>"",BF9<>""),IF(IF(BE9>BF9,"1",IF(BE9<BF9,"2","X"))="2",1,0),0) -> 0 | AP17: =IF(AND(BE4<>"",BF4<>""),IF(IF(BE4>BF4,"1",IF(BE4<BF4,"2","X"))="1",1,0),0)+IF(AND(BE5<>"",BF5<>""),IF(IF(BE5>BF5,"1",IF(BE5<BF5,"2","X"))="2",1,0),0)+IF(AND(BE6<>"",BF6<>""),IF(IF(BE6>BF6,"1",IF(BE6<BF6,"2","X"))="1",1,0),0)+IF(AND(BE7<>"",BF7<>""),IF(IF(BE7>BF7,"1",IF(BE7<BF7,"2","X"))="2",1,0),0)+IF(AND(BE8<>"",BF8<>""),IF(IF(BE8>BF8,"1",IF(BE8<BF8,"2","X"))="2",1,0),0)+IF(AND(BE9<>"",BF9<>""),IF(IF(BE9>BF9,"1",IF(BE9<BF9,"2","X"))="X",1,0),0) -> 0 | AS17: =IF(AND(BE4<>"",BF4<>""),IF(IF(BE4>BF4,"1",IF(BE4<BF4,"2","X"))="X",1,0),0)+IF(AND(BE5<>"",BF5<>""),IF(IF(BE5>BF5,"1",IF(BE5<BF5,"2","X"))="2",1,0),0)+IF(AND(BE6<>"",BF6<>""),IF(IF(BE6>BF6,"1",IF(BE6<BF6,"2","X"))="1",1,0),0)+IF(AND(BE7<>"",BF7<>""),IF(IF(BE7>BF7,"1",IF(BE7<BF7,"2","X"))="2",1,0),0)+IF(AND(BE8<>"",BF8<>""),IF(IF(BE8>BF8,"1",IF(BE8<BF8,"2","X"))="X",1,0),0)+IF(AND(BE9<>"",BF9<>""),IF(IF(BE9>BF9,"1",IF(BE9<BF9,"2","X"))="1",1,0),0) -> 0 | AV17: =IF(AND(BE4<>"",BF4<>""),IF(IF(BE4>BF4,"1",IF(BE4<BF4,"2","X"))="1",1,0),0)+IF(AND(BE5<>"",BF5<>""),IF(IF(BE5>BF5,"1",IF(BE5<BF5,"2","X"))="X",1,0),0)+IF(AND(BE6<>"",BF6<>""),IF(IF(BE6>BF6,"1",IF(BE6<BF6,"2","X"))="1",1,0),0)+IF(AND(BE7<>"",BF7<>""),IF(IF(BE7>BF7,"1",IF(BE7<BF7,"2","X"))="2",1,0),0)+IF(AND(BE8<>"",BF8<>""),IF(IF(BE8>BF8,"1",IF(BE8<BF8,"2","X"))="X",1,0),0)+IF(AND(BE9<>"",BF9<>""),IF(IF(BE9>BF9,"1",IF(BE9<BF9,"2","X"))="X",1,0),0) -> 0 | AY17: =IF(AND(BE4<>"",BF4<>""),IF(IF(BE4>BF4,"1",IF(BE4<BF4,"2","X"))="1",1,0),0)+IF(AND(BE5<>"",BF5<>""),IF(IF(BE5>BF5,"1",IF(BE5<BF5,"2","X"))="2",1,0),0)+IF(AND(BE6<>"",BF6<>""),IF(IF(BE6>BF6,"1",IF(BE6<BF6,"2","X"))="1",1,0),0)+IF(AND(BE7<>"",BF7<>""),IF(IF(BE7>BF7,"1",IF(BE7<BF7,"2","X"))="2",1,0),0)+IF(AND(BE8<>"",BF8<>""),IF(IF(BE8>BF8,"1",IF(BE8<BF8,"2","X"))="2",1,0),0)+IF(AND(BE9<>"",BF9<>""),IF(IF(BE9>BF9,"1",IF(BE9<BF9,"2","X"))="1",1,0),0) -> 0 | BB17: =IF(AND(BE4<>"",BF4<>""),IF(IF(BE4>BF4,"1",IF(BE4<BF4,"2","X"))="1",1,0),0)+IF(AND(BE5<>"",BF5<>""),IF(IF(BE5>BF5,"1",IF(BE5<BF5,"2","X"))="X",1,0),0)+IF(AND(BE6<>"",BF6<>""),IF(IF(BE6>BF6,"1",IF(BE6<BF6,"2","X"))="X",1,0),0)+IF(AND(BE7<>"",BF7<>""),IF(IF(BE7>BF7,"1",IF(BE7<BF7,"2","X"))="2",1,0),0)+IF(AND(BE8<>"",BF8<>""),IF(IF(BE8>BF8,"1",IF(BE8<BF8,"2","X"))="1",1,0),0)+IF(AND(BE9<>"",BF9<>""),IF(IF(BE9>BF9,"1",IF(BE9<BF9,"2","X"))="X",1,0),0) -> 0
A18: Marcadores exactos (3 pts c/u) | F18: =IF(AND(BE4<>"",BF4<>""),IF(AND(BE4=3,BF4=1),3,0),0)+IF(AND(BE5<>"",BF5<>""),IF(AND(BE5=1,BF5=1),3,0),0)+IF(AND(BE6<>"",BF6<>""),IF(AND(BE6=2,BF6=0),3,0),0)+IF(AND(BE7<>"",BF7<>""),IF(AND(BE7=1,BF7=1),3,0),0)+IF(AND(BE8<>"",BF8<>""),IF(AND(BE8=0,BF8=1),3,0),0)+IF(AND(BE9<>"",BF9<>""),IF(AND(BE9=0,BF9=2),3,0),0) -> 0 | I18: =0+0+0+0+0+0 -> 0 | L18: =IF(AND(BE4<>"",BF4<>""),IF(AND(BE4=3,BF4=1),3,0),0)+IF(AND(BE5<>"",BF5<>""),IF(AND(BE5=1,BF5=1),3,0),0)+IF(AND(BE6<>"",BF6<>""),IF(AND(BE6=2,BF6=2),3,0),0)+IF(AND(BE7<>"",BF7<>""),IF(AND(BE7=0,BF7=3),3,0),0)+IF(AND(BE8<>"",BF8<>""),IF(AND(BE8=0,BF8=2),3,0),0)+IF(AND(BE9<>"",BF9<>""),IF(AND(BE9=1,BF9=3),3,0),0) -> 0 | O18: =IF(AND(BE4<>"",BF4<>""),IF(AND(BE4=2,BF4=0),3,0),0)+IF(AND(BE5<>"",BF5<>""),IF(AND(BE5=1,BF5=1),3,0),0)+IF(AND(BE6<>"",BF6<>""),IF(AND(BE6=1,BF6=0),3,0),0)+IF(AND(BE7<>"",BF7<>""),IF(AND(BE7=1,BF7=2),3,0),0)+IF(AND(BE8<>"",BF8<>""),IF(AND(BE8=0,BF8=2),3,0),0)+IF(AND(BE9<>"",BF9<>""),IF(AND(BE9=1,BF9=1),3,0),0) -> 0 | R18: =IF(AND(BE4<>"",BF4<>""),IF(AND(BE4=3,BF4=1),3,0),0)+IF(AND(BE5<>"",BF5<>""),IF(AND(BE5=2,BF5=1),3,0),0)+IF(AND(BE6<>"",BF6<>""),IF(AND(BE6=2,BF6=0),3,0),0)+IF(AND(BE7<>"",BF7<>""),IF(AND(BE7=2,BF7=2),3,0),0)+IF(AND(BE8<>"",BF8<>""),IF(AND(BE8=1,BF8=2),3,0),0)+IF(AND(BE9<>"",BF9<>""),IF(AND(BE9=3,BF9=1),3,0),0) -> 0 | U18: =IF(AND(BE4<>"",BF4<>""),IF(AND(BE4=3,BF4=0),3,0),0)+IF(AND(BE5<>"",BF5<>""),IF(AND(BE5=2,BF5=2),3,0),0)+IF(AND(BE6<>"",BF6<>""),IF(AND(BE6=2,BF6=1),3,0),0)+IF(AND(BE7<>"",BF7<>""),IF(AND(BE7=1,BF7=3),3,0),0)+IF(AND(BE8<>"",BF8<>""),IF(AND(BE8=1,BF8=1),3,0),0)+IF(AND(BE9<>"",BF9<>""),IF(AND(BE9=0,BF9=2),3,0),0) -> 0 | X18: =IF(AND(BE4<>"",BF4<>""),IF(AND(BE4=2,BF4=1),3,0),0)+IF(AND(BE5<>"",BF5<>""),IF(AND(BE5=1,BF5=1),3,0),0)+IF(AND(BE6<>"",BF6<>""),IF(AND(BE6=3,BF6=2),3,0),0)+IF(AND(BE7<>"",BF7<>""),IF(AND(BE7=0,BF7=1),3,0),0)+IF(AND(BE8<>"",BF8<>""),IF(AND(BE8=1,BF8=1),3,0),0)+IF(AND(BE9<>"",BF9<>""),IF(AND(BE9=0,BF9=2),3,0),0) -> 0 | AA18: =IF(AND(BE4<>"",BF4<>""),IF(AND(BE4=2,BF4=0),3,0),0)+IF(AND(BE5<>"",BF5<>""),IF(AND(BE5=1,BF5=1),3,0),0)+IF(AND(BE6<>"",BF6<>""),IF(AND(BE6=1,BF6=1),3,0),0)+IF(AND(BE7<>"",BF7<>""),IF(AND(BE7=0,BF7=2),3,0),0)+IF(AND(BE8<>"",BF8<>""),IF(AND(BE8=1,BF8=2),3,0),0)+IF(AND(BE9<>"",BF9<>""),IF(AND(BE9=0,BF9=1),3,0),0) -> 0 | AD18: =IF(AND(BE4<>"",BF4<>""),IF(AND(BE4=1,BF4=0),3,0),0)+IF(AND(BE5<>"",BF5<>""),IF(AND(BE5=1,BF5=1),3,0),0)+IF(AND(BE6<>"",BF6<>""),IF(AND(BE6=1,BF6=1),3,0),0)+IF(AND(BE7<>"",BF7<>""),IF(AND(BE7=0,BF7=2),3,0),0)+IF(AND(BE8<>"",BF8<>""),IF(AND(BE8=2,BF8=2),3,0),0)+IF(AND(BE9<>"",BF9<>""),IF(AND(BE9=0,BF9=1),3,0),0) -> 0 | AG18: =IF(AND(BE4<>"",BF4<>""),IF(AND(BE4=3,BF4=1),3,0),0)+IF(AND(BE5<>"",BF5<>""),IF(AND(BE5=1,BF5=1),3,0),0)+IF(AND(BE6<>"",BF6<>""),IF(AND(BE6=1,BF6=2),3,0),0)+IF(AND(BE7<>"",BF7<>""),IF(AND(BE7=1,BF7=2),3,0),0)+IF(AND(BE8<>"",BF8<>""),IF(AND(BE8=1,BF8=1),3,0),0)+IF(AND(BE9<>"",BF9<>""),IF(AND(BE9=1,BF9=2),3,0),0) -> 0 | AJ18: =0+0+0+0+0+0 -> 0 | AM18: =IF(AND(BE4<>"",BF4<>""),IF(AND(BE4=2,BF4=0),3,0),0)+IF(AND(BE5<>"",BF5<>""),IF(AND(BE5=1,BF5=1),3,0),0)+IF(AND(BE6<>"",BF6<>""),IF(AND(BE6=2,BF6=1),3,0),0)+IF(AND(BE7<>"",BF7<>""),IF(AND(BE7=0,BF7=1),3,0),0)+IF(AND(BE8<>"",BF8<>""),IF(AND(BE8=1,BF8=2),3,0),0)+IF(AND(BE9<>"",BF9<>""),IF(AND(BE9=1,BF9=2),3,0),0) -> 0 | AP18: =IF(AND(BE4<>"",BF4<>""),IF(AND(BE4=2,BF4=0),3,0),0)+IF(AND(BE5<>"",BF5<>""),IF(AND(BE5=1,BF5=1),3,0),0)+IF(AND(BE6<>"",BF6<>""),IF(AND(BE6=1,BF6=1),3,0),0)+IF(AND(BE7<>"",BF7<>""),IF(AND(BE7=0,BF7=2),3,0),0)+IF(AND(BE8<>"",BF8<>""),IF(AND(BE8=0,BF8=1),3,0),0)+IF(AND(BE9<>"",BF9<>""),IF(AND(BE9=0,BF9=1),3,0),0) -> 0 | AS18: =IF(AND(BE4<>"",BF4<>""),IF(AND(BE4=1,BF4=1),3,0),0)+IF(AND(BE5<>"",BF5<>""),IF(AND(BE5=1,BF5=3),3,0),0)+IF(AND(BE6<>"",BF6<>""),IF(AND(BE6=2,BF6=0),3,0),0)+IF(AND(BE7<>"",BF7<>""),IF(AND(BE7=1,BF7=2),3,0),0)+IF(AND(BE8<>"",BF8<>""),IF(AND(BE8=2,BF8=2),3,0),0)+IF(AND(BE9<>"",BF9<>""),IF(AND(BE9=2,BF9=0),3,0),0) -> 0 | AV18: =IF(AND(BE4<>"",BF4<>""),IF(AND(BE4=2,BF4=1),3,0),0)+IF(AND(BE5<>"",BF5<>""),IF(AND(BE5=1,BF5=1),3,0),0)+IF(AND(BE6<>"",BF6<>""),IF(AND(BE6=2,BF6=1),3,0),0)+IF(AND(BE7<>"",BF7<>""),IF(AND(BE7=1,BF7=2),3,0),0)+IF(AND(BE8<>"",BF8<>""),IF(AND(BE8=1,BF8=1),3,0),0)+IF(AND(BE9<>"",BF9<>""),IF(AND(BE9=1,BF9=1),3,0),0) -> 0 | AY18: =IF(AND(BE4<>"",BF4<>""),IF(AND(BE4=2,BF4=0),3,0),0)+IF(AND(BE5<>"",BF5<>""),IF(AND(BE5=1,BF5=1),3,0),0)+IF(AND(BE6<>"",BF6<>""),IF(AND(BE6=1,BF6=1),3,0),0)+IF(AND(BE7<>"",BF7<>""),IF(AND(BE7=1,BF7=0),3,0),0)+IF(AND(BE8<>"",BF8<>""),IF(AND(BE8=1,BF8=3),3,0),0)+IF(AND(BE9<>"",BF9<>""),IF(AND(BE9=2,BF9=2),3,0),0) -> 0 | BB18: =IF(AND(BE4<>"",BF4<>""),IF(AND(BE4=2,BF4=0),3,0),0)+IF(AND(BE5<>"",BF5<>""),IF(AND(BE5=1,BF5=1),3,0),0)+IF(AND(BE6<>"",BF6<>""),IF(AND(BE6=1,BF6=1),3,0),0)+IF(AND(BE7<>"",BF7<>""),IF(AND(BE7=0,BF7=1),3,0),0)+IF(AND(BE8<>"",BF8<>""),IF(AND(BE8=2,BF8=1),3,0),0)+IF(AND(BE9<>"",BF9<>""),IF(AND(BE9=1,BF9=1),3,0),0) -> 0
A19: Clasificación 1º(4pt) 2º(2pt) 3º(1pt) | F19: =IF(C12<>"",IF(C12="México",4,0),0)+IF(C13<>"",IF(C13="Corea del Sur",2,0),0)+IF(C14<>"",IF(C14="Rep. Checa",1,0),0) -> 0 | I19: =0+0+0 -> 0 | L19: =IF(C12<>"",IF(C12="México",4,0),0)+IF(C13<>"",IF(C13="Corea del Sur",2,0),0)+IF(C14<>"",IF(C14="República Checa",1,0),0) -> 0 | O19: =IF(C12<>"",IF(C12="México",4,0),0)+IF(C13<>"",IF(C13="Corea del Sur",2,0),0)+IF(C14<>"",IF(C14="Rep. Checa",1,0),0) -> 0 | R19: =IF(C12<>"",IF(C12="México",4,0),0)+IF(C13<>"",IF(C13="Corea del Sur",2,0),0)+IF(C14<>"",IF(C14="Sudáfrica",1,0),0) -> 0 | U19: =IF(C12<>"",IF(C12="México",4,0),0)+IF(C13<>"",IF(C13="Rep. Checa",2,0),0)+IF(C14<>"",IF(C14="Corea del Sur",1,0),0) -> 0 | X19: =IF(C12<>"",IF(C12="Mexico",4,0),0)+IF(C13<>"",IF(C13="Corea del Sur",2,0),0)+IF(C14<>"",IF(C14="Rep. Checa",1,0),0) -> 0 | AA19: =IF(C12<>"",IF(C12="México",4,0),0)+IF(C13<>"",IF(C13="Corea del Sur",2,0),0)+IF(C14<>"",IF(C14="Rep. Checa",1,0),0) -> 0 | AD19: =IF(C12<>"",IF(C12="REPUBLICA CHECA",4,0),0)+IF(C13<>"",IF(C13="MÉXICO",2,0),0)+IF(C14<>"",IF(C14="COREA DEL SUR",1,0),0) -> 0 | AG19: =IF(C12<>"",IF(C12="COREA DEL SUR",4,0),0)+IF(C13<>"",IF(C13="MÉXICO",2,0),0)+IF(C14<>"",IF(C14="REP.CHECA",1,0),0) -> 0 | AJ19: =0+0+0 -> 0 | AM19: =IF(C12<>"",IF(C12="Mexico",4,0),0)+IF(C13<>"",IF(C13="Chequia",2,0),0)+IF(C14<>"",IF(C14="Corea",1,0),0) -> 0 | AP19: =IF(C12<>"",IF(C12="México",4,0),0)+IF(C13<>"",IF(C13="Rep. Checa",2,0),0)+IF(C14<>"",IF(C14="Corea del Sur",1,0),0) -> 0 | AS19: =IF(C12<>"",IF(C12="Re. Checa",4,0),0)+IF(C13<>"",IF(C13="Mexico",2,0),0)+IF(C14<>"",IF(C14="Sudafrica",1,0),0) -> 0 | AV19: =IF(C12<>"",IF(C12="mexico",4,0),0)+IF(C13<>"",IF(C13="republica checa",2,0),0)+IF(C14<>"",IF(C14="corea del sur",1,0),0) -> 0 | AY19: =IF(C12<>"",IF(C12="Mexico",4,0),0)+IF(C13<>"",IF(C13="Rep. Checa",2,0),0)+IF(C14<>"",IF(C14="Corea del Sur",1,0),0) -> 0 | BB19: =IF(C12<>"",IF(C12="Rep. Checa",4,0),0)+IF(C13<>"",IF(C13="Mexico",2,0),0)+IF(C14<>"",IF(C14="Corea del sur",1,0),0) -> 0
A20: ⭐ TOTAL DEL GRUPO | F20: =F17+F18+F19 -> 0 | I20: =I17+I18+I19 -> 0 | L20: =L17+L18+L19 -> 0 | O20: =O17+O18+O19 -> 0 | R20: =R17+R18+R19 -> 0 | U20: =U17+U18+U19 -> 0 | X20: =X17+X18+X19 -> 0 | AA20: =AA17+AA18+AA19 -> 0 | AD20: =AD17+AD18+AD19 -> 0 | AG20: =AG17+AG18+AG19 -> 0 | AJ20: =AJ17+AJ18+AJ19 -> 0 | AM20: =AM17+AM18+AM19 -> 0 | AP20: =AP17+AP18+AP19 -> 0 | AS20: =AS17+AS18+AS19 -> 0 | AV20: =AV17+AV18+AV19 -> 0 | AY20: =AY17+AY18+AY19 -> 0 | BB20: =BB17+BB18+BB19 -> 0
F21: =F20 -> 0 | I21: =I20 -> 0 | L21: =L20 -> 0 | O21: =O20 -> 0 | R21: =R20 -> 0 | U21: =U20 -> 0 | X21: =X20 -> 0 | AA21: =AA20 -> 0 | AD21: =AD20 -> 0 | AG21: =AG20 -> 0 | AJ21: =AJ20 -> 0 | AM21: =AM20 -> 0 | AP21: =AP20 -> 0 | AS21: =AS20 -> 0 | AV21: =AV20 -> 0 | AY21: =AY20 -> 0 | BB21: =BB20 -> 0

Sheet Grupo B
A1: ⚽ GRUPO B — Canadá · Bosnia-Herz. · Qatar · Suiza
A2: JOR. | B2: LOCAL | C2: VS | D2: VISITANTE | E2: FECHA | F2: Aaron | I2: Aitor | L2: Coco | O2: Danel | R2: Guille | U2: Jaime | X2: JonBel | AA2: JonMo | AD2: JuanLu | AG2: JuanRo | AJ2: LuisMi | AM2: Mario | AP2: Pablo | AS2: Roberto | AV2: Txiki | AY2: Wiki | BB2: Xabi | BE2: ✅ RESULTADO REAL
F3: L | G3: V | H3: ± | I3: L | J3: V | K3: ± | L3: L | M3: V | N3: ± | O3: L | P3: V | Q3: ± | R3: L | S3: V | T3: ± | U3: L | V3: V | W3: ± | X3: L | Y3: V | Z3: ± | AA3: L | AB3: V | AC3: ± | AD3: L | AE3: V | AF3: ± | AG3: L | AH3: V | AI3: ± | AJ3: L | AK3: V | AL3: ± | AM3: L | AN3: V | AO3: ± | AP3: L | AQ3: V | AR3: ± | AS3: L | AT3: V | AU3: ± | AV3: L | AW3: V | AX3: ± | AY3: L | AZ3: V | BA3: ± | BB3: L | BC3: V | BD3: ± | BE3: GOL L | BF3: GOL V
A4: 1 | B4: Canadá | C4: vs | D4: Bosnia-Herz. | F4: 2 | G4: 1 | H4: 1 | L4: 1 | M4: 1 | N4: 2 | O4: 2 | P4: 1 | Q4: 1 | R4: 3 | S4: 0 | T4: 1 | U4: 1 | V4: 1 | W4: X | X4: 1 | Y4: 1 | Z4: 2 | AA4: 2 | AB4: 0 | AC4: 1 | AD4: 1 | AE4: 1 | AF4: 2 | AG4: 2 | AH4: 2 | AI4: X | AM4: 1 | AN4: 1 | AO4: X | AP4: 1 | AQ4: 1 | AR4: 1 | AS4: 1 | AT4: 1 | AU4: X | AV4: 1 | AW4: 2 | AX4: 2 | AY4: 0 | AZ4: 1 | BA4: X | BB4: 2 | BC4: 1 | BD4: 1
A5: 1 | B5: Qatar | C5: vs | D5: Suiza | F5: 0 | G5: 4 | H5: 2 | L5: 0 | M5: 3 | N5: 2 | O5: 0 | P5: 2 | Q5: 2 | R5: 1 | S5: 3 | T5: 2 | U5: 1 | V5: 3 | W5: 2 | X5: 0 | Y5: 3 | Z5: 2 | AA5: 0 | AB5: 2 | AC5: 2 | AD5: 0 | AE5: 2 | AF5: 2 | AG5: 0 | AH5: 2 | AI5: 2 | AM5: 0 | AN5: 2 | AO5: 2 | AP5: 0 | AQ5: 2 | AR5: 2 | AS5: 1 | AT5: 2 | AU5: 2 | AV5: 0 | AW5: 3 | AX5: 2 | AY5: 1 | AZ5: 2 | BA5: 2 | BB5: 0 | BC5: 2 | BD5: 2
A6: 2 | B6: Canadá | C6: vs | D6: Qatar | F6: 1 | G6: 1 | H6: 1 | L6: 3 | M6: 1 | N6: 1 | O6: 2 | P6: 0 | Q6: 1 | R6: 2 | S6: 0 | T6: 1 | U6: 0 | V6: 0 | W6: X | X6: 2 | Y6: 0 | Z6: 1 | AA6: 3 | AB6: 0 | AC6: 1 | AD6: 1 | AE6: 0 | AF6: X | AG6: 1 | AH6: 0 | AI6: X | AM6: 2 | AN6: 1 | AO6: 1 | AP6: 3 | AQ6: 0 | AR6: 1 | AS6: 2 | AT6: 1 | AU6: 1 | AV6: 2 | AW6: 1 | AX6: 1 | AY6: 1 | AZ6: 0 | BA6: X | BB6: 1 | BC6: 0 | BD6: 1
A7: 2 | B7: Suiza | C7: vs | D7: Bosnia-Herz. | F7: 2 | G7: 0 | H7: 1 | L7: 3 | M7: 1 | N7: 1 | O7: 2 | P7: 0 | Q7: 1 | R7: 3 | S7: 1 | T7: 1 | U7: 2 | V7: 0 | W7: 1 | X7: 1 | Y7: 1 | Z7: X | AA7: 2 | AB7: 1 | AC7: 1 | AD7: 1 | AE7: 0 | AF7: X | AG7: 2 | AH7: 1 | AI7: 1 | AM7: 2 | AN7: 0 | AO7: 1 | AP7: 1 | AQ7: 0 | AR7: 1 | AS7: 2 | AT7: 0 | AU7: 1 | AV7: 2 | AW7: 1 | AX7: 1 | AY7: 2 | AZ7: 2 | BA7: 1 | BB7: 2 | BC7: 1 | BD7: 1
A8: 3 | B8: Bosnia-Herz. | C8: vs | D8: Qatar | F8: 0 | G8: 0 | H8: X | L8: 1 | M8: 0 | N8: X | O8: 1 | P8: 0 | Q8: 1 | R8: 1 | S8: 1 | T8: 2 | U8: 1 | V8: 0 | W8: 1 | X8: 2 | Y8: 0 | Z8: 1 | AA8: 2 | AB8: 1 | AC8: 1 | AD8: 2 | AE8: 1 | AF8: 1 | AG8: 2 | AH8: 1 | AI8: 1 | AM8: 1 | AN8: 1 | AO8: X | AP8: 2 | AQ8: 0 | AR8: 1 | AS8: 0 | AT8: 0 | AU8: X | AV8: 2 | AW8: 1 | AX8: 1 | AY8: 2 | AZ8: 1 | BA8: 1 | BB8: 2 | BC8: 1 | BD8: 1
A9: 3 | B9: Suiza | C9: vs | D9: Canadá | F9: 1 | G9: 0 | H9: 1 | L9: 3 | M9: 1 | N9: 1 | O9: 1 | P9: 1 | Q9: X | R9: 2 | S9: 3 | T9: 2 | U9: 2 | V9: 1 | W9: 1 | X9: 1 | Y9: 0 | Z9: X | AA9: 1 | AB9: 1 | AC9: X | AD9: 1 | AE9: 1 | AF9: 2 | AG9: 1 | AH9: 1 | AI9: 1 | AM9: 1 | AN9: 1 | AO9: X | AP9: 2 | AQ9: 1 | AR9: X | AS9: 2 | AT9: 1 | AU9: 1 | AV9: 1 | AW9: 0 | AX9: 1 | AY9: 1 | AZ9: 0 | BA9: X | BB9: 1 | BC9: 1 | BD9: X
A11: 📊 CLASIFICACIÓN DEL GRUPO (rellena los equipos reales en amarillo)
A12: 🥇 1º | F12: Suiza | L12: Suiza | O12: Suiza | R12: Suiza | U12: Suiza | X12: Bosnia-Herz. | AA12: Suiza | AD12: SUIZA | AG12: SUIZA | AM12: Suiza | AP12: Suiza | AS12: Suiza | AV12: suiza | AY12: Suiza | BB12: Suiza
A13: 🥈 2º | F13: Canadá | L13: Bosnia -Herz | O13: Canadá | R13: Canadá | U13: Bosnia-Herz. | X13: Suiza | AA13: Canadá | AD13: BOSNIA | AG13: CANADÁ | AM13: Canadá | AP13: Canadá | AS13: Canada | AV13: canada | AY13: Bosnia | BB13: Canadá
A14: 🥉 3º | L14: Canadá | O14: Bosnia-Herz. | R14: Qatar | U14: Canadá | X14: Canadá | AA14: Bosnia-Herz. | AD14: CANADA | AG14: BOSNIA-HERZEGOVINA | AM14: Bosnia | AP14: Bosnia-Herzegovina | AS14: Bosnia-Herz | AV14: bosnia Herzegovina | AY14: Qatar | BB14: Bosnia-Herz
A16: 🎯 PUNTOS TOTALES
A17: Signos acertados (1 pt c/u) | F17: =IF(AND(BE4<>"",BF4<>""),IF(IF(BE4>BF4,"1",IF(BE4<BF4,"2","X"))="1",1,0),0)+IF(AND(BE5<>"",BF5<>""),IF(IF(BE5>BF5,"1",IF(BE5<BF5,"2","X"))="2",1,0),0)+IF(AND(BE6<>"",BF6<>""),IF(IF(BE6>BF6,"1",IF(BE6<BF6,"2","X"))="1",1,0),0)+IF(AND(BE7<>"",BF7<>""),IF(IF(BE7>BF7,"1",IF(BE7<BF7,"2","X"))="1",1,0),0)+IF(AND(BE8<>"",BF8<>""),IF(IF(BE8>BF8,"1",IF(BE8<BF8,"2","X"))="X",1,0),0)+IF(AND(BE9<>"",BF9<>""),IF(IF(BE9>BF9,"1",IF(BE9<BF9,"2","X"))="1",1,0),0) -> 0 | I17: =0+0+0+0+0+0 -> 0 | L17: =IF(AND(BE4<>"",BF4<>""),IF(IF(BE4>BF4,"1",IF(BE4<BF4,"2","X"))="2",1,0),0)+IF(AND(BE5<>"",BF5<>""),IF(IF(BE5>BF5,"1",IF(BE5<BF5,"2","X"))="2",1,0),0)+IF(AND(BE6<>"",BF6<>""),IF(IF(BE6>BF6,"1",IF(BE6<BF6,"2","X"))="1",1,0),0)+IF(AND(BE7<>"",BF7<>""),IF(IF(BE7>BF7,"1",IF(BE7<BF7,"2","X"))="1",1,0),0)+IF(AND(BE8<>"",BF8<>""),IF(IF(BE8>BF8,"1",IF(BE8<BF8,"2","X"))="X",1,0),0)+IF(AND(BE9<>"",BF9<>""),IF(IF(BE9>BF9,"1",IF(BE9<BF9,"2","X"))="1",1,0),0) -> 0 | O17: =IF(AND(BE4<>"",BF4<>""),IF(IF(BE4>BF4,"1",IF(BE4<BF4,"2","X"))="1",1,0),0)+IF(AND(BE5<>"",BF5<>""),IF(IF(BE5>BF5,"1",IF(BE5<BF5,"2","X"))="2",1,0),0)+IF(AND(BE6<>"",BF6<>""),IF(IF(BE6>BF6,"1",IF(BE6<BF6,"2","X"))="1",1,0),0)+IF(AND(BE7<>"",BF7<>""),IF(IF(BE7>BF7,"1",IF(BE7<BF7,"2","X"))="1",1,0),0)+IF(AND(BE8<>"",BF8<>""),IF(IF(BE8>BF8,"1",IF(BE8<BF8,"2","X"))="1",1,0),0)+IF(AND(BE9<>"",BF9<>""),IF(IF(BE9>BF9,"1",IF(BE9<BF9,"2","X"))="X",1,0),0) -> 0 | R17: =IF(AND(BE4<>"",BF4<>""),IF(IF(BE4>BF4,"1",IF(BE4<BF4,"2","X"))="1",1,0),0)+IF(AND(BE5<>"",BF5<>""),IF(IF(BE5>BF5,"1",IF(BE5<BF5,"2","X"))="2",1,0),0)+IF(AND(BE6<>"",BF6<>""),IF(IF(BE6>BF6,"1",IF(BE6<BF6,"2","X"))="1",1,0),0)+IF(AND(BE7<>"",BF7<>""),IF(IF(BE7>BF7,"1",IF(BE7<BF7,"2","X"))="1",1,0),0)+IF(AND(BE8<>"",BF8<>""),IF(IF(BE8>BF8,"1",IF(BE8<BF8,"2","X"))="2",1,0),0)+IF(AND(BE9<>"",BF9<>""),IF(IF(BE9>BF9,"1",IF(BE9<BF9,"2","X"))="2",1,0),0) -> 0 | U17: =IF(AND(BE4<>"",BF4<>""),IF(IF(BE4>BF4,"1",IF(BE4<BF4,"2","X"))="X",1,0),0)+IF(AND(BE5<>"",BF5<>""),IF(IF(BE5>BF5,"1",IF(BE5<BF5,"2","X"))="2",1,0),0)+IF(AND(BE6<>"",BF6<>""),IF(IF(BE6>BF6,"1",IF(BE6<BF6,"2","X"))="X",1,0),0)+IF(AND(BE7<>"",BF7<>""),IF(IF(BE7>BF7,"1",IF(BE7<BF7,"2","X"))="1",1,0),0)+IF(AND(BE8<>"",BF8<>""),IF(IF(BE8>BF8,"1",IF(BE8<BF8,"2","X"))="1",1,0),0)+IF(AND(BE9<>"",BF9<>""),IF(IF(BE9>BF9,"1",IF(BE9<BF9,"2","X"))="1",1,0),0) -> 0 | X17: =IF(AND(BE4<>"",BF4<>""),IF(IF(BE4>BF4,"1",IF(BE4<BF4,"2","X"))="2",1,0),0)+IF(AND(BE5<>"",BF5<>""),IF(IF(BE5>BF5,"1",IF(BE5<BF5,"2","X"))="2",1,0),0)+IF(AND(BE6<>"",BF6<>""),IF(IF(BE6>BF6,"1",IF(BE6<BF6,"2","X"))="1",1,0),0)+IF(AND(BE7<>"",BF7<>""),IF(IF(BE7>BF7,"1",IF(BE7<BF7,"2","X"))="X",1,0),0)+IF(AND(BE8<>"",BF8<>""),IF(IF(BE8>BF8,"1",IF(BE8<BF8,"2","X"))="1",1,0),0)+IF(AND(BE9<>"",BF9<>""),IF(IF(BE9>BF9,"1",IF(BE9<BF9,"2","X"))="X",1,0),0) -> 0 | AA17: =IF(AND(BE4<>"",BF4<>""),IF(IF(BE4>BF4,"1",IF(BE4<BF4,"2","X"))="1",1,0),0)+IF(AND(BE5<>"",BF5<>""),IF(IF(BE5>BF5,"1",IF(BE5<BF5,"2","X"))="2",1,0),0)+IF(AND(BE6<>"",BF6<>""),IF(IF(BE6>BF6,"1",IF(BE6<BF6,"2","X"))="1",1,0),0)+IF(AND(BE7<>"",BF7<>""),IF(IF(BE7>BF7,"1",IF(BE7<BF7,"2","X"))="1",1,0),0)+IF(AND(BE8<>"",BF8<>""),IF(IF(BE8>BF8,"1",IF(BE8<BF8,"2","X"))="1",1,0),0)+IF(AND(BE9<>"",BF9<>""),IF(IF(BE9>BF9,"1",IF(BE9<BF9,"2","X"))="X",1,0),0) -> 0 | AD17: =IF(AND(BE4<>"",BF4<>""),IF(IF(BE4>BF4,"1",IF(BE4<BF4,"2","X"))="2",1,0),0)+IF(AND(BE5<>"",BF5<>""),IF(IF(BE5>BF5,"1",IF(BE5<BF5,"2","X"))="2",1,0),0)+IF(AND(BE6<>"",BF6<>""),IF(IF(BE6>BF6,"1",IF(BE6<BF6,"2","X"))="X",1,0),0)+IF(AND(BE7<>"",BF7<>""),IF(IF(BE7>BF7,"1",IF(BE7<BF7,"2","X"))="X",1,0),0)+IF(AND(BE8<>"",BF8<>""),IF(IF(BE8>BF8,"1",IF(BE8<BF8,"2","X"))="1",1,0),0)+IF(AND(BE9<>"",BF9<>""),IF(IF(BE9>BF9,"1",IF(BE9<BF9,"2","X"))="2",1,0),0) -> 0 | AG17: =IF(AND(BE4<>"",BF4<>""),IF(IF(BE4>BF4,"1",IF(BE4<BF4,"2","X"))="X",1,0),0)+IF(AND(BE5<>"",BF5<>""),IF(IF(BE5>BF5,"1",IF(BE5<BF5,"2","X"))="2",1,0),0)+IF(AND(BE6<>"",BF6<>""),IF(IF(BE6>BF6,"1",IF(BE6<BF6,"2","X"))="X",1,0),0)+IF(AND(BE7<>"",BF7<>""),IF(IF(BE7>BF7,"1",IF(BE7<BF7,"2","X"))="1",1,0),0)+IF(AND(BE8<>"",BF8<>""),IF(IF(BE8>BF8,"1",IF(BE8<BF8,"2","X"))="1",1,0),0)+IF(AND(BE9<>"",BF9<>""),IF(IF(BE9>BF9,"1",IF(BE9<BF9,"2","X"))="1",1,0),0) -> 0 | AJ17: =0+0+0+0+0+0 -> 0 | AM17: =IF(AND(BE4<>"",BF4<>""),IF(IF(BE4>BF4,"1",IF(BE4<BF4,"2","X"))="X",1,0),0)+IF(AND(BE5<>"",BF5<>""),IF(IF(BE5>BF5,"1",IF(BE5<BF5,"2","X"))="2",1,0),0)+IF(AND(BE6<>"",BF6<>""),IF(IF(BE6>BF6,"1",IF(BE6<BF6,"2","X"))="1",1,0),0)+IF(AND(BE7<>"",BF7<>""),IF(IF(BE7>BF7,"1",IF(BE7<BF7,"2","X"))="1",1,0),0)+IF(AND(BE8<>"",BF8<>""),IF(IF(BE8>BF8,"1",IF(BE8<BF8,"2","X"))="X",1,0),0)+IF(AND(BE9<>"",BF9<>""),IF(IF(BE9>BF9,"1",IF(BE9<BF9,"2","X"))="X",1,0),0) -> 0 | AP17: =IF(AND(BE4<>"",BF4<>""),IF(IF(BE4>BF4,"1",IF(BE4<BF4,"2","X"))="1",1,0),0)+IF(AND(BE5<>"",BF5<>""),IF(IF(BE5>BF5,"1",IF(BE5<BF5,"2","X"))="2",1,0),0)+IF(AND(BE6<>"",BF6<>""),IF(IF(BE6>BF6,"1",IF(BE6<BF6,"2","X"))="1",1,0),0)+IF(AND(BE7<>"",BF7<>""),IF(IF(BE7>BF7,"1",IF(BE7<BF7,"2","X"))="1",1,0),0)+IF(AND(BE8<>"",BF8<>""),IF(IF(BE8>BF8,"1",IF(BE8<BF8,"2","X"))="1",1,0),0)+IF(AND(BE9<>"",BF9<>""),IF(IF(BE9>BF9,"1",IF(BE9<BF9,"2","X"))="X",1,0),0) -> 0 | AS17: =IF(AND(BE4<>"",BF4<>""),IF(IF(BE4>BF4,"1",IF(BE4<BF4,"2","X"))="X",1,0),0)+IF(AND(BE5<>"",BF5<>""),IF(IF(BE5>BF5,"1",IF(BE5<BF5,"2","X"))="2",1,0),0)+IF(AND(BE6<>"",BF6<>""),IF(IF(BE6>BF6,"1",IF(BE6<BF6,"2","X"))="1",1,0),0)+IF(AND(BE7<>"",BF7<>""),IF(IF(BE7>BF7,"1",IF(BE7<BF7,"2","X"))="1",1,0),0)+IF(AND(BE8<>"",BF8<>""),IF(IF(BE8>BF8,"1",IF(BE8<BF8,"2","X"))="X",1,0),0)+IF(AND(BE9<>"",BF9<>""),IF(IF(BE9>BF9,"1",IF(BE9<BF9,"2","X"))="1",1,0),0) -> 0 | AV17: =IF(AND(BE4<>"",BF4<>""),IF(IF(BE4>BF4,"1",IF(BE4<BF4,"2","X"))="2",1,0),0)+IF(AND(BE5<>"",BF5<>""),IF(IF(BE5>BF5,"1",IF(BE5<BF5,"2","X"))="2",1,0),0)+IF(AND(BE6<>"",BF6<>""),IF(IF(BE6>BF6,"1",IF(BE6<BF6,"2","X"))="1",1,0),0)+IF(AND(BE7<>"",BF7<>""),IF(IF(BE7>BF7,"1",IF(BE7<BF7,"2","X"))="1",1,0),0)+IF(AND(BE8<>"",BF8<>""),IF(IF(BE8>BF8,"1",IF(BE8<BF8,"2","X"))="1",1,0),0)+IF(AND(BE9<>"",BF9<>""),IF(IF(BE9>BF9,"1",IF(BE9<BF9,"2","X"))="1",1,0),0) -> 0 | AY17: =IF(AND(BE4<>"",BF4<>""),IF(IF(BE4>BF4,"1",IF(BE4<BF4,"2","X"))="X",1,0),0)+IF(AND(BE5<>"",BF5<>""),IF(IF(BE5>BF5,"1",IF(BE5<BF5,"2","X"))="2",1,0),0)+IF(AND(BE6<>"",BF6<>""),IF(IF(BE6>BF6,"1",IF(BE6<BF6,"2","X"))="X",1,0),0)+IF(AND(BE7<>"",BF7<>""),IF(IF(BE7>BF7,"1",IF(BE7<BF7,"2","X"))="1",1,0),0)+IF(AND(BE8<>"",BF8<>""),IF(IF(BE8>BF8,"1",IF(BE8<BF8,"2","X"))="1",1,0),0)+IF(AND(BE9<>"",BF9<>""),IF(IF(BE9>BF9,"1",IF(BE9<BF9,"2","X"))="X",1,0),0) -> 0 | BB17: =IF(AND(BE4<>"",BF4<>""),IF(IF(BE4>BF4,"1",IF(BE4<BF4,"2","X"))="1",1,0),0)+IF(AND(BE5<>"",BF5<>""),IF(IF(BE5>BF5,"1",IF(BE5<BF5,"2","X"))="2",1,0),0)+IF(AND(BE6<>"",BF6<>""),IF(IF(BE6>BF6,"1",IF(BE6<BF6,"2","X"))="1",1,0),0)+IF(AND(BE7<>"",BF7<>""),IF(IF(BE7>BF7,"1",IF(BE7<BF7,"2","X"))="1",1,0),0)+IF(AND(BE8<>"",BF8<>""),IF(IF(BE8>BF8,"1",IF(BE8<BF8,"2","X"))="1",1,0),0)+IF(AND(BE9<>"",BF9<>""),IF(IF(BE9>BF9,"1",IF(BE9<BF9,"2","X"))="X",1,0),0) -> 0
A18: Marcadores exactos (3 pts c/u) | F18: =IF(AND(BE4<>"",BF4<>""),IF(AND(BE4=2,BF4=1),3,0),0)+IF(AND(BE5<>"",BF5<>""),IF(AND(BE5=0,BF5=4),3,0),0)+IF(AND(BE6<>"",BF6<>""),IF(AND(BE6=1,BF6=1),3,0),0)+IF(AND(BE7<>"",BF7<>""),IF(AND(BE7=2,BF7=0),3,0),0)+IF(AND(BE8<>"",BF8<>""),IF(AND(BE8=0,BF8=0),3,0),0)+IF(AND(BE9<>"",BF9<>""),IF(AND(BE9=1,BF9=0),3,0),0) -> 0 | I18: =0+0+0+0+0+0 -> 0 | L18: =IF(AND(BE4<>"",BF4<>""),IF(AND(BE4=1,BF4=1),3,0),0)+IF(AND(BE5<>"",BF5<>""),IF(AND(BE5=0,BF5=3),3,0),0)+IF(AND(BE6<>"",BF6<>""),IF(AND(BE6=3,BF6=1),3,0),0)+IF(AND(BE7<>"",BF7<>""),IF(AND(BE7=3,BF7=1),3,0),0)+IF(AND(BE8<>"",BF8<>""),IF(AND(BE8=1,BF8=0),3,0),0)+IF(AND(BE9<>"",BF9<>""),IF(AND(BE9=3,BF9=1),3,0),0) -> 0 | O18: =IF(AND(BE4<>"",BF4<>""),IF(AND(BE4=2,BF4=1),3,0),0)+IF(AND(BE5<>"",BF5<>""),IF(AND(BE5=0,BF5=2),3,0),0)+IF(AND(BE6<>"",BF6<>""),IF(AND(BE6=2,BF6=0),3,0),0)+IF(AND(BE7<>"",BF7<>""),IF(AND(BE7=2,BF7=0),3,0),0)+IF(AND(BE8<>"",BF8<>""),IF(AND(BE8=1,BF8=0),3,0),0)+IF(AND(BE9<>"",BF9<>""),IF(AND(BE9=1,BF9=1),3,0),0) -> 0 | R18: =IF(AND(BE4<>"",BF4<>""),IF(AND(BE4=3,BF4=0),3,0),0)+IF(AND(BE5<>"",BF5<>""),IF(AND(BE5=1,BF5=3),3,0),0)+IF(AND(BE6<>"",BF6<>""),IF(AND(BE6=2,BF6=0),3,0),0)+IF(AND(BE7<>"",BF7<>""),IF(AND(BE7=3,BF7=1),3,0),0)+IF(AND(BE8<>"",BF8<>""),IF(AND(BE8=1,BF8=1),3,0),0)+IF(AND(BE9<>"",BF9<>""),IF(AND(BE9=2,BF9=3),3,0),0) -> 0 | U18: =IF(AND(BE4<>"",BF4<>""),IF(AND(BE4=1,BF4=1),3,0),0)+IF(AND(BE5<>"",BF5<>""),IF(AND(BE5=1,BF5=3),3,0),0)+IF(AND(BE6<>"",BF6<>""),IF(AND(BE6=0,BF6=0),3,0),0)+IF(AND(BE7<>"",BF7<>""),IF(AND(BE7=2,BF7=0),3,0),0)+IF(AND(BE8<>"",BF8<>""),IF(AND(BE8=1,BF8=0),3,0),0)+IF(AND(BE9<>"",BF9<>""),IF(AND(BE9=2,BF9=1),3,0),0) -> 0 | X18: =IF(AND(BE4<>"",BF4<>""),IF(AND(BE4=1,BF4=1),3,0),0)+IF(AND(BE5<>"",BF5<>""),IF(AND(BE5=0,BF5=3),3,0),0)+IF(AND(BE6<>"",BF6<>""),IF(AND(BE6=2,BF6=0),3,0),0)+IF(AND(BE7<>"",BF7<>""),IF(AND(BE7=1,BF7=1),3,0),0)+IF(AND(BE8<>"",BF8<>""),IF(AND(BE8=2,BF8=0),3,0),0)+IF(AND(BE9<>"",BF9<>""),IF(AND(BE9=1,BF9=0),3,0),0) -> 0 | AA18: =IF(AND(BE4<>"",BF4<>""),IF(AND(BE4=2,BF4=0),3,0),0)+IF(AND(BE5<>"",BF5<>""),IF(AND(BE5=0,BF5=2),3,0),0)+IF(AND(BE6<>"",BF6<>""),IF(AND(BE6=3,BF6=0),3,0),0)+IF(AND(BE7<>"",BF7<>""),IF(AND(BE7=2,BF7=1),3,0),0)+IF(AND(BE8<>"",BF8<>""),IF(AND(BE8=2,BF8=1),3,0),0)+IF(AND(BE9<>"",BF9<>""),IF(AND(BE9=1,BF9=1),3,0),0) -> 0 | AD18: =IF(AND(BE4<>"",BF4<>""),IF(AND(BE4=1,BF4=1),3,0),0)+IF(AND(BE5<>"",BF5<>""),IF(AND(BE5=0,BF5=2),3,0),0)+IF(AND(BE6<>"",BF6<>""),IF(AND(BE6=1,BF6=0),3,0),0)+IF(AND(BE7<>"",BF7<>""),IF(AND(BE7=1,BF7=0),3,0),0)+IF(AND(BE8<>"",BF8<>""),IF(AND(BE8=2,BF8=1),3,0),0)+IF(AND(BE9<>"",BF9<>""),IF(AND(BE9=1,BF9=1),3,0),0) -> 0 | AG18: =IF(AND(BE4<>"",BF4<>""),IF(AND(BE4=2,BF4=2),3,0),0)+IF(AND(BE5<>"",BF5<>""),IF(AND(BE5=0,BF5=2),3,0),0)+IF(AND(BE6<>"",BF6<>""),IF(AND(BE6=1,BF6=0),3,0),0)+IF(AND(BE7<>"",BF7<>""),IF(AND(BE7=2,BF7=1),3,0),0)+IF(AND(BE8<>"",BF8<>""),IF(AND(BE8=2,BF8=1),3,0),0)+IF(AND(BE9<>"",BF9<>""),IF(AND(BE9=1,BF9=1),3,0),0) -> 0 | AJ18: =0+0+0+0+0+0 -> 0 | AM18: =IF(AND(BE4<>"",BF4<>""),IF(AND(BE4=1,BF4=1),3,0),0)+IF(AND(BE5<>"",BF5<>""),IF(AND(BE5=0,BF5=2),3,0),0)+IF(AND(BE6<>"",BF6<>""),IF(AND(BE6=2,BF6=1),3,0),0)+IF(AND(BE7<>"",BF7<>""),IF(AND(BE7=2,BF7=0),3,0),0)+IF(AND(BE8<>"",BF8<>""),IF(AND(BE8=1,BF8=1),3,0),0)+IF(AND(BE9<>"",BF9<>""),IF(AND(BE9=1,BF9=1),3,0),0) -> 0 | AP18: =IF(AND(BE4<>"",BF4<>""),IF(AND(BE4=1,BF4=1),3,0),0)+IF(AND(BE5<>"",BF5<>""),IF(AND(BE5=0,BF5=2),3,0),0)+IF(AND(BE6<>"",BF6<>""),IF(AND(BE6=3,BF6=0),3,0),0)+IF(AND(BE7<>"",BF7<>""),IF(AND(BE7=1,BF7=0),3,0),0)+IF(AND(BE8<>"",BF8<>""),IF(AND(BE8=2,BF8=0),3,0),0)+IF(AND(BE9<>"",BF9<>""),IF(AND(BE9=2,BF9=1),3,0),0) -> 0 | AS18: =IF(AND(BE4<>"",BF4<>""),IF(AND(BE4=1,BF4=1),3,0),0)+IF(AND(BE5<>"",BF5<>""),IF(AND(BE5=1,BF5=2),3,0),0)+IF(AND(BE6<>"",BF6<>""),IF(AND(BE6=2,BF6=1),3,0),0)+IF(AND(BE7<>"",BF7<>""),IF(AND(BE7=2,BF7=0),3,0),0)+IF(AND(BE8<>"",BF8<>""),IF(AND(BE8=0,BF8=0),3,0),0)+IF(AND(BE9<>"",BF9<>""),IF(AND(BE9=2,BF9=1),3,0),0) -> 0 | AV18: =IF(AND(BE4<>"",BF4<>""),IF(AND(BE4=1,BF4=2),3,0),0)+IF(AND(BE5<>"",BF5<>""),IF(AND(BE5=0,BF5=3),3,0),0)+IF(AND(BE6<>"",BF6<>""),IF(AND(BE6=2,BF6=1),3,0),0)+IF(AND(BE7<>"",BF7<>""),IF(AND(BE7=2,BF7=1),3,0),0)+IF(AND(BE8<>"",BF8<>""),IF(AND(BE8=2,BF8=1),3,0),0)+IF(AND(BE9<>"",BF9<>""),IF(AND(BE9=1,BF9=0),3,0),0) -> 0 | AY18: =IF(AND(BE4<>"",BF4<>""),IF(AND(BE4=0,BF4=1),3,0),0)+IF(AND(BE5<>"",BF5<>""),IF(AND(BE5=1,BF5=2),3,0),0)+IF(AND(BE6<>"",BF6<>""),IF(AND(BE6=1,BF6=0),3,0),0)+IF(AND(BE7<>"",BF7<>""),IF(AND(BE7=2,BF7=2),3,0),0)+IF(AND(BE8<>"",BF8<>""),IF(AND(BE8=2,BF8=1),3,0),0)+IF(AND(BE9<>"",BF9<>""),IF(AND(BE9=1,BF9=0),3,0),0) -> 0 | BB18: =IF(AND(BE4<>"",BF4<>""),IF(AND(BE4=2,BF4=1),3,0),0)+IF(AND(BE5<>"",BF5<>""),IF(AND(BE5=0,BF5=2),3,0),0)+IF(AND(BE6<>"",BF6<>""),IF(AND(BE6=1,BF6=0),3,0),0)+IF(AND(BE7<>"",BF7<>""),IF(AND(BE7=2,BF7=1),3,0),0)+IF(AND(BE8<>"",BF8<>""),IF(AND(BE8=2,BF8=1),3,0),0)+IF(AND(BE9<>"",BF9<>""),IF(AND(BE9=1,BF9=1),3,0),0) -> 0
A19: Clasificación 1º(4pt) 2º(2pt) 3º(1pt) | F19: =IF(C12<>"",IF(C12="Suiza",4,0),0)+IF(C13<>"",IF(C13="Canadá",2,0),0)+0 -> 0 | I19: =0+0+0 -> 0 | L19: =IF(C12<>"",IF(C12="Suiza",4,0),0)+IF(C13<>"",IF(C13="Bosnia -Herz",2,0),0)+IF(C14<>"",IF(C14="Canadá",1,0),0) -> 0 | O19: =IF(C12<>"",IF(C12="Suiza",4,0),0)+IF(C13<>"",IF(C13="Canadá",2,0),0)+IF(C14<>"",IF(C14="Bosnia-Herz.",1,0),0) -> 0 | R19: =IF(C12<>"",IF(C12="Suiza",4,0),0)+IF(C13<>"",IF(C13="Canadá",2,0),0)+IF(C14<>"",IF(C14="Qatar",1,0),0) -> 0 | U19: =IF(C12<>"",IF(C12="Suiza",4,0),0)+IF(C13<>"",IF(C13="Bosnia-Herz.",2,0),0)+IF(C14<>"",IF(C14="Canadá",1,0),0) -> 0 | X19: =IF(C12<>"",IF(C12="Bosnia-Herz.",4,0),0)+IF(C13<>"",IF(C13="Suiza",2,0),0)+IF(C14<>"",IF(C14="Canadá",1,0),0) -> 0 | AA19: =IF(C12<>"",IF(C12="Suiza",4,0),0)+IF(C13<>"",IF(C13="Canadá",2,0),0)+IF(C14<>"",IF(C14="Bosnia-Herz.",1,0),0) -> 0 | AD19: =IF(C12<>"",IF(C12="SUIZA",4,0),0)+IF(C13<>"",IF(C13="BOSNIA",2,0),0)+IF(C14<>"",IF(C14="CANADA",1,0),0) -> 0 | AG19: =IF(C12<>"",IF(C12="SUIZA",4,0),0)+IF(C13<>"",IF(C13="CANADÁ",2,0),0)+IF(C14<>"",IF(C14="BOSNIA-HERZEGOVINA",1,0),0) -> 0 | AJ19: =0+0+0 -> 0 | AM19: =IF(C12<>"",IF(C12="Suiza",4,0),0)+IF(C13<>"",IF(C13="Canadá",2,0),0)+IF(C14<>"",IF(C14="Bosnia",1,0),0) -> 0 | AP19: =IF(C12<>"",IF(C12="Suiza",4,0),0)+IF(C13<>"",IF(C13="Canadá",2,0),0)+IF(C14<>"",IF(C14="Bosnia-Herzegovina",1,0),0) -> 0 | AS19: =IF(C12<>"",IF(C12="Suiza",4,0),0)+IF(C13<>"",IF(C13="Canada",2,0),0)+IF(C14<>"",IF(C14="Bosnia-Herz",1,0),0) -> 0 | AV19: =IF(C12<>"",IF(C12="suiza",4,0),0)+IF(C13<>"",IF(C13="canada",2,0),0)+IF(C14<>"",IF(C14="bosnia Herzegovina",1,0),0) -> 0 | AY19: =IF(C12<>"",IF(C12="Suiza",4,0),0)+IF(C13<>"",IF(C13="Bosnia",2,0),0)+IF(C14<>"",IF(C14="Qatar",1,0),0) -> 0 | BB19: =IF(C12<>"",IF(C12="Suiza",4,0),0)+IF(C13<>"",IF(C13="Canadá",2,0),0)+IF(C14<>"",IF(C14="Bosnia-Herz",1,0),0) -> 0
A20: ⭐ TOTAL DEL GRUPO | F20: =F17+F18+F19 -> 0 | I20: =I17+I18+I19 -> 0 | L20: =L17+L18+L19 -> 0 | O20: =O17+O18+O19 -> 0 | R20: =R17+R18+R19 -> 0 | U20: =U17+U18+U19 -> 0 | X20: =X17+X18+X19 -> 0 | AA20: =AA17+AA18+AA19 -> 0 | AD20: =AD17+AD18+AD19 -> 0 | AG20: =AG17+AG18+AG19 -> 0 | AJ20: =AJ17+AJ18+AJ19 -> 0 | AM20: =AM17+AM18+AM19 -> 0 | AP20: =AP17+AP18+AP19 -> 0 | AS20: =AS17+AS18+AS19 -> 0 | AV20: =AV17+AV18+AV19 -> 0 | AY20: =AY17+AY18+AY19 -> 0 | BB20: =BB17+BB18+BB19 -> 0
F21: =F20 -> 0 | I21: =I20 -> 0 | L21: =L20 -> 0 | O21: =O20 -> 0 | R21: =R20 -> 0 | U21: =U20 -> 0 | X21: =X20 -> 0 | AA21: =AA20 -> 0 | AD21: =AD20 -> 0 | AG21: =AG20 -> 0 | AJ21: =AJ20 -> 0 | AM21: =AM20 -> 0 | AP21: =AP20 -> 0 | AS21: =AS20 -> 0 | AV21: =AV20 -> 0 | AY21: =AY20 -> 0 | BB21: =BB20 -> 0

Sheet Grupo C
A1: ⚽ GRUPO C — Brasil · Marruecos · Haití · Escocia
A2: JOR. | B2: LOCAL | C2: VS | D2: VISITANTE | E2: FECHA | F2: Aaron | I2: Aitor | L2: Coco | O2: Danel | R2: Guille | U2: Jaime | X2: JonBel | AA2: JonMo | AD2: JuanLu | AG2: JuanRo | AJ2: LuisMi | AM2: Mario | AP2: Pablo | AS2: Roberto | AV2: Txiki | AY2: Wiki | BB2: Xabi | BE2: ✅ RESULTADO REAL
F3: L | G3: V | H3: ± | I3: L | J3: V | K3: ± | L3: L | M3: V | N3: ± | O3: L | P3: V | Q3: ± | R3: L | S3: V | T3: ± | U3: L | V3: V | W3: ± | X3: L | Y3: V | Z3: ± | AA3: L | AB3: V | AC3: ± | AD3: L | AE3: V | AF3: ± | AG3: L | AH3: V | AI3: ± | AJ3: L | AK3: V | AL3: ± | AM3: L | AN3: V | AO3: ± | AP3: L | AQ3: V | AR3: ± | AS3: L | AT3: V | AU3: ± | AV3: L | AW3: V | AX3: ± | AY3: L | AZ3: V | BA3: ± | BB3: L | BC3: V | BD3: ± | BE3: GOL L | BF3: GOL V
A4: 1 | B4: Brasil | C4: vs | D4: Marruecos | F4: 2 | G4: 1 | H4: 1 | L4: 3 | M4: 1 | N4: 1 | O4: 2 | P4: 0 | Q4: 1 | R4: 2 | S4: 3 | T4: 2 | U4: 2 | V4: 1 | W4: X | X4: 0 | Y4: 1 | Z4: X | AA4: 2 | AB4: 0 | AC4: 1 | AD4: 2 | AE4: 2 | AF4: 1 | AG4: 2 | AH4: 1 | AI4: 1 | AM4: 3 | AN4: 1 | AO4: 1 | AP4: 3 | AQ4: 1 | AR4: 1 | AS4: 3 | AT4: 1 | AU4: 1 | AV4: 3 | AW4: 1 | AX4: 1 | AY4: 2 | AZ4: 2 | BA4: 2 | BB4: 2 | BC4: 1 | BD4: 1
A5: 1 | B5: Haití | C5: vs | D5: Escocia | F5: 0 | G5: 2 | H5: 2 | L5: 0 | M5: 1 | N5: 2 | O5: 0 | P5: 2 | Q5: 2 | R5: 1 | S5: 3 | T5: 2 | U5: 0 | V5: 4 | W5: 2 | X5: 0 | Y5: 3 | Z5: 2 | AA5: 0 | AB5: 2 | AC5: 2 | AD5: 0 | AE5: 3 | AF5: 2 | AG5: 1 | AH5: 1 | AI5: 1 | AM5: 1 | AN5: 2 | AO5: 2 | AP5: 0 | AQ5: 2 | AR5: 2 | AS5: 0 | AT5: 2 | AU5: 2 | AV5: 1 | AW5: 2 | AX5: 2 | AY5: 0 | AZ5: 1 | BA5: 2 | BB5: 0 | BC5: 2 | BD5: 2
A6: 2 | B6: Brasil | C6: vs | D6: Haití | F6: 4 | G6: 0 | H6: 1 | L6: 5 | M6: 1 | N6: 1 | O6: 3 | P6: 0 | Q6: 1 | R6: 6 | S6: 1 | T6: 1 | U6: 5 | V6: 0 | W6: 1 | X6: 5 | Y6: 0 | Z6: 1 | AA6: 4 | AB6: 0 | AC6: 1 | AD6: 2 | AE6: 0 | AF6: 1 | AG6: 3 | AH6: 1 | AI6: 1 | AM6: 3 | AN6: 0 | AO6: 1 | AP6: 4 | AQ6: 0 | AR6: 1 | AS6: 4 | AT6: 1 | AU6: 1 | AV6: 4 | AW6: 0 | AX6: 1 | AY6: 3 | AZ6: 0 | BA6: 1 | BB6: 4 | BC6: 0 | BD6: 1
A7: 2 | B7: Escocia | C7: vs | D7: Marruecos | F7: 0 | G7: 3 | H7: 2 | L7: 0 | M7: 3 | N7: 2 | O7: 1 | P7: 2 | Q7: 2 | R7: 1 | S7: 4 | T7: 2 | U7: 1 | V7: 2 | W7: 2 | X7: 1 | Y7: 1 | Z7: X | AA7: 0 | AB7: 1 | AC7: 2 | AD7: 1 | AE7: 2 | AF7: X | AG7: 1 | AH7: 2 | AI7: 2 | AM7: 1 | AN7: 1 | AO7: X | AP7: 1 | AQ7: 2 | AR7: 2 | AS7: 0 | AT7: 2 | AU7: 2 | AV7: 1 | AW7: 2 | AX7: 2 | AY7: 1 | AZ7: 3 | BA7: 2 | BB7: 1 | BC7: 1 | BD7: X
A8: 3 | B8: Marruecos | C8: vs | D8: Haití | F8: 2 | G8: 0 | H8: 1 | L8: 4 | M8: 0 | N8: 1 | O8: 2 | P8: 0 | Q8: 1 | R8: 5 | S8: 1 | T8: 1 | U8: 4 | V8: 0 | W8: 1 | X8: 4 | Y8: 0 | Z8: 1 | AA8: 3 | AB8: 0 | AC8: 1 | AD8: 3 | AE8: 0 | AF8: 1 | AG8: 3 | AH8: 0 | AI8: 1 | AM8: 2 | AN8: 1 | AO8: 1 | AP8: 3 | AQ8: 0 | AR8: 1 | AS8: 2 | AT8: 0 | AU8: 1 | AV8: 3 | AW8: 0 | AX8: 1 | AY8: 4 | AZ8: 0 | BA8: 1 | BB8: 3 | BC8: 0 | BD8: 1
A9: 3 | B9: Escocia | C9: vs | D9: Brasil | F9: 1 | G9: 4 | H9: 2 | L9: 1 | M9: 3 | N9: 2 | O9: 0 | P9: 2 | Q9: 2 | R9: 1 | S9: 4 | T9: 2 | U9: 1 | V9: 3 | W9: 2 | X9: 1 | Y9: 2 | Z9: 2 | AA9: 0 | AB9: 2 | AC9: 2 | AD9: 1 | AE9: 1 | AF9: 1 | AG9: 1 | AH9: 2 | AI9: 2 | AM9: 0 | AN9: 2 | AO9: 2 | AP9: 1 | AQ9: 3 | AR9: 2 | AS9: 1 | AT9: 4 | AU9: 2 | AV9: 0 | AW9: 2 | AX9: 2 | AY9: 1 | AZ9: 4 | BA9: 2 | BB9: 1 | BC9: 3 | BD9: 2
A11: 📊 CLASIFICACIÓN DEL GRUPO (rellena los equipos reales en amarillo)
A12: 🥇 1º | F12: Brasil | L12: Brasil | O12: Brasil | R12: Marruecos | U12: Brasil | X12: Marruecos | AA12: Brasil | AD12: MARRUECOS | AG12: BRASIL | AM12: Brasil | AP12: Brasil | AS12: Brasil | AV12: brasil | AY12: Marruecos | BB12: Brasil
A13: 🥈 2º | F13: Marruecos | L13: Marruecos | O13: Marruecos | R13: Brazil | U13: Marruecos | X13: Brasil | AA13: Marruecos | AD13: BRASIL | AG13: MARRUECOS | AM13: Marruecos | AP13: Marruecos | AS13: Marruecos | AV13: marruecos | AY13: Brasil | BB13: Marruecos
A14: 🥉 3º | F14: Escocia | L14: Escocia | O14: Escocia | R14: Escocia | U14: Escocia | X14: Escocia | AA14: Escocia | AD14: ESCOCIA | AG14: ESCOCIA | AM14: Escocia | AP14: Escocia | AS14: Escocia | AV14: escocia | AY14: Escocia | BB14: Escocia
A16: 🎯 PUNTOS TOTALES
A17: Signos acertados (1 pt c/u) | F17: =IF(AND(BE4<>"",BF4<>""),IF(IF(BE4>BF4,"1",IF(BE4<BF4,"2","X"))="1",1,0),0)+IF(AND(BE5<>"",BF5<>""),IF(IF(BE5>BF5,"1",IF(BE5<BF5,"2","X"))="2",1,0),0)+IF(AND(BE6<>"",BF6<>""),IF(IF(BE6>BF6,"1",IF(BE6<BF6,"2","X"))="1",1,0),0)+IF(AND(BE7<>"",BF7<>""),IF(IF(BE7>BF7,"1",IF(BE7<BF7,"2","X"))="2",1,0),0)+IF(AND(BE8<>"",BF8<>""),IF(IF(BE8>BF8,"1",IF(BE8<BF8,"2","X"))="1",1,0),0)+IF(AND(BE9<>"",BF9<>""),IF(IF(BE9>BF9,"1",IF(BE9<BF9,"2","X"))="2",1,0),0) -> 0 | I17: =0+0+0+0+0+0 -> 0 | L17: =IF(AND(BE4<>"",BF4<>""),IF(IF(BE4>BF4,"1",IF(BE4<BF4,"2","X"))="1",1,0),0)+IF(AND(BE5<>"",BF5<>""),IF(IF(BE5>BF5,"1",IF(BE5<BF5,"2","X"))="2",1,0),0)+IF(AND(BE6<>"",BF6<>""),IF(IF(BE6>BF6,"1",IF(BE6<BF6,"2","X"))="1",1,0),0)+IF(AND(BE7<>"",BF7<>""),IF(IF(BE7>BF7,"1",IF(BE7<BF7,"2","X"))="2",1,0),0)+IF(AND(BE8<>"",BF8<>""),IF(IF(BE8>BF8,"1",IF(BE8<BF8,"2","X"))="1",1,0),0)+IF(AND(BE9<>"",BF9<>""),IF(IF(BE9>BF9,"1",IF(BE9<BF9,"2","X"))="2",1,0),0) -> 0 | O17: =IF(AND(BE4<>"",BF4<>""),IF(IF(BE4>BF4,"1",IF(BE4<BF4,"2","X"))="1",1,0),0)+IF(AND(BE5<>"",BF5<>""),IF(IF(BE5>BF5,"1",IF(BE5<BF5,"2","X"))="2",1,0),0)+IF(AND(BE6<>"",BF6<>""),IF(IF(BE6>BF6,"1",IF(BE6<BF6,"2","X"))="1",1,0),0)+IF(AND(BE7<>"",BF7<>""),IF(IF(BE7>BF7,"1",IF(BE7<BF7,"2","X"))="2",1,0),0)+IF(AND(BE8<>"",BF8<>""),IF(IF(BE8>BF8,"1",IF(BE8<BF8,"2","X"))="1",1,0),0)+IF(AND(BE9<>"",BF9<>""),IF(IF(BE9>BF9,"1",IF(BE9<BF9,"2","X"))="2",1,0),0) -> 0 | R17: =IF(AND(BE4<>"",BF4<>""),IF(IF(BE4>BF4,"1",IF(BE4<BF4,"2","X"))="2",1,0),0)+IF(AND(BE5<>"",BF5<>""),IF(IF(BE5>BF5,"1",IF(BE5<BF5,"2","X"))="2",1,0),0)+IF(AND(BE6<>"",BF6<>""),IF(IF(BE6>BF6,"1",IF(BE6<BF6,"2","X"))="1",1,0),0)+IF(AND(BE7<>"",BF7<>""),IF(IF(BE7>BF7,"1",IF(BE7<BF7,"2","X"))="2",1,0),0)+IF(AND(BE8<>"",BF8<>""),IF(IF(BE8>BF8,"1",IF(BE8<BF8,"2","X"))="1",1,0),0)+IF(AND(BE9<>"",BF9<>""),IF(IF(BE9>BF9,"1",IF(BE9<BF9,"2","X"))="2",1,0),0) -> 0 | U17: =IF(AND(BE4<>"",BF4<>""),IF(IF(BE4>BF4,"1",IF(BE4<BF4,"2","X"))="X",1,0),0)+IF(AND(BE5<>"",BF5<>""),IF(IF(BE5>BF5,"1",IF(BE5<BF5,"2","X"))="2",1,0),0)+IF(AND(BE6<>"",BF6<>""),IF(IF(BE6>BF6,"1",IF(BE6<BF6,"2","X"))="1",1,0),0)+IF(AND(BE7<>"",BF7<>""),IF(IF(BE7>BF7,"1",IF(BE7<BF7,"2","X"))="2",1,0),0)+IF(AND(BE8<>"",BF8<>""),IF(IF(BE8>BF8,"1",IF(BE8<BF8,"2","X"))="1",1,0),0)+IF(AND(BE9<>"",BF9<>""),IF(IF(BE9>BF9,"1",IF(BE9<BF9,"2","X"))="2",1,0),0) -> 0 | X17: =IF(AND(BE4<>"",BF4<>""),IF(IF(BE4>BF4,"1",IF(BE4<BF4,"2","X"))="X",1,0),0)+IF(AND(BE5<>"",BF5<>""),IF(IF(BE5>BF5,"1",IF(BE5<BF5,"2","X"))="2",1,0),0)+IF(AND(BE6<>"",BF6<>""),IF(IF(BE6>BF6,"1",IF(BE6<BF6,"2","X"))="1",1,0),0)+IF(AND(BE7<>"",BF7<>""),IF(IF(BE7>BF7,"1",IF(BE7<BF7,"2","X"))="X",1,0),0)+IF(AND(BE8<>"",BF8<>""),IF(IF(BE8>BF8,"1",IF(BE8<BF8,"2","X"))="1",1,0),0)+IF(AND(BE9<>"",BF9<>""),IF(IF(BE9>BF9,"1",IF(BE9<BF9,"2","X"))="2",1,0),0) -> 0 | AA17: =IF(AND(BE4<>"",BF4<>""),IF(IF(BE4>BF4,"1",IF(BE4<BF4,"2","X"))="1",1,0),0)+IF(AND(BE5<>"",BF5<>""),IF(IF(BE5>BF5,"1",IF(BE5<BF5,"2","X"))="2",1,0),0)+IF(AND(BE6<>"",BF6<>""),IF(IF(BE6>BF6,"1",IF(BE6<BF6,"2","X"))="1",1,0),0)+IF(AND(BE7<>"",BF7<>""),IF(IF(BE7>BF7,"1",IF(BE7<BF7,"2","X"))="2",1,0),0)+IF(AND(BE8<>"",BF8<>""),IF(IF(BE8>BF8,"1",IF(BE8<BF8,"2","X"))="1",1,0),0)+IF(AND(BE9<>"",BF9<>""),IF(IF(BE9>BF9,"1",IF(BE9<BF9,"2","X"))="2",1,0),0) -> 0 | AD17: =IF(AND(BE4<>"",BF4<>""),IF(IF(BE4>BF4,"1",IF(BE4<BF4,"2","X"))="1",1,0),0)+IF(AND(BE5<>"",BF5<>""),IF(IF(BE5>BF5,"1",IF(BE5<BF5,"2","X"))="2",1,0),0)+IF(AND(BE6<>"",BF6<>""),IF(IF(BE6>BF6,"1",IF(BE6<BF6,"2","X"))="1",1,0),0)+IF(AND(BE7<>"",BF7<>""),IF(IF(BE7>BF7,"1",IF(BE7<BF7,"2","X"))="X",1,0),0)+IF(AND(BE8<>"",BF8<>""),IF(IF(BE8>BF8,"1",IF(BE8<BF8,"2","X"))="1",1,0),0)+IF(AND(BE9<>"",BF9<>""),IF(IF(BE9>BF9,"1",IF(BE9<BF9,"2","X"))="1",1,0),0) -> 0 | AG17: =IF(AND(BE4<>"",BF4<>""),IF(IF(BE4>BF4,"1",IF(BE4<BF4,"2","X"))="1",1,0),0)+IF(AND(BE5<>"",BF5<>""),IF(IF(BE5>BF5,"1",IF(BE5<BF5,"2","X"))="1",1,0),0)+IF(AND(BE6<>"",BF6<>""),IF(IF(BE6>BF6,"1",IF(BE6<BF6,"2","X"))="1",1,0),0)+IF(AND(BE7<>"",BF7<>""),IF(IF(BE7>BF7,"1",IF(BE7<BF7,"2","X"))="2",1,0),0)+IF(AND(BE8<>"",BF8<>""),IF(IF(BE8>BF8,"1",IF(BE8<BF8,"2","X"))="1",1,0),0)+IF(AND(BE9<>"",BF9<>""),IF(IF(BE9>BF9,"1",IF(BE9<BF9,"2","X"))="2",1,0),0) -> 0 | AJ17: =0+0+0+0+0+0 -> 0 | AM17: =IF(AND(BE4<>"",BF4<>""),IF(IF(BE4>BF4,"1",IF(BE4<BF4,"2","X"))="1",1,0),0)+IF(AND(BE5<>"",BF5<>""),IF(IF(BE5>BF5,"1",IF(BE5<BF5,"2","X"))="2",1,0),0)+IF(AND(BE6<>"",BF6<>""),IF(IF(BE6>BF6,"1",IF(BE6<BF6,"2","X"))="1",1,0),0)+IF(AND(BE7<>"",BF7<>""),IF(IF(BE7>BF7,"1",IF(BE7<BF7,"2","X"))="X",1,0),0)+IF(AND(BE8<>"",BF8<>""),IF(IF(BE8>BF8,"1",IF(BE8<BF8,"2","X"))="1",1,0),0)+IF(AND(BE9<>"",BF9<>""),IF(IF(BE9>BF9,"1",IF(BE9<BF9,"2","X"))="2",1,0),0) -> 0 | AP17: =IF(AND(BE4<>"",BF4<>""),IF(IF(BE4>BF4,"1",IF(BE4<BF4,"2","X"))="1",1,0),0)+IF(AND(BE5<>"",BF5<>""),IF(IF(BE5>BF5,"1",IF(BE5<BF5,"2","X"))="2",1,0),0)+IF(AND(BE6<>"",BF6<>""),IF(IF(BE6>BF6,"1",IF(BE6<BF6,"2","X"))="1",1,0),0)+IF(AND(BE7<>"",BF7<>""),IF(IF(BE7>BF7,"1",IF(BE7<BF7,"2","X"))="2",1,0),0)+IF(AND(BE8<>"",BF8<>""),IF(IF(BE8>BF8,"1",IF(BE8<BF8,"2","X"))="1",1,0),0)+IF(AND(BE9<>"",BF9<>""),IF(IF(BE9>BF9,"1",IF(BE9<BF9,"2","X"))="2",1,0),0) -> 0 | AS17: =IF(AND(BE4<>"",BF4<>""),IF(IF(BE4>BF4,"1",IF(BE4<BF4,"2","X"))="1",1,0),0)+IF(AND(BE5<>"",BF5<>""),IF(IF(BE5>BF5,"1",IF(BE5<BF5,"2","X"))="2",1,0),0)+IF(AND(BE6<>"",BF6<>""),IF(IF(BE6>BF6,"1",IF(BE6<BF6,"2","X"))="1",1,0),0)+IF(AND(BE7<>"",BF7<>""),IF(IF(BE7>BF7,"1",IF(BE7<BF7,"2","X"))="2",1,0),0)+IF(AND(BE8<>"",BF8<>""),IF(IF(BE8>BF8,"1",IF(BE8<BF8,"2","X"))="1",1,0),0)+IF(AND(BE9<>"",BF9<>""),IF(IF(BE9>BF9,"1",IF(BE9<BF9,"2","X"))="2",1,0),0) -> 0 | AV17: =IF(AND(BE4<>"",BF4<>""),IF(IF(BE4>BF4,"1",IF(BE4<BF4,"2","X"))="1",1,0),0)+IF(AND(BE5<>"",BF5<>""),IF(IF(BE5>BF5,"1",IF(BE5<BF5,"2","X"))="2",1,0),0)+IF(AND(BE6<>"",BF6<>""),IF(IF(BE6>BF6,"1",IF(BE6<BF6,"2","X"))="1",1,0),0)+IF(AND(BE7<>"",BF7<>""),IF(IF(BE7>BF7,"1",IF(BE7<BF7,"2","X"))="2",1,0),0)+IF(AND(BE8<>"",BF8<>""),IF(IF(BE8>BF8,"1",IF(BE8<BF8,"2","X"))="1",1,0),0)+IF(AND(BE9<>"",BF9<>""),IF(IF(BE9>BF9,"1",IF(BE9<BF9,"2","X"))="2",1,0),0) -> 0 | AY17: =IF(AND(BE4<>"",BF4<>""),IF(IF(BE4>BF4,"1",IF(BE4<BF4,"2","X"))="2",1,0),0)+IF(AND(BE5<>"",BF5<>""),IF(IF(BE5>BF5,"1",IF(BE5<BF5,"2","X"))="2",1,0),0)+IF(AND(BE6<>"",BF6<>""),IF(IF(BE6>BF6,"1",IF(BE6<BF6,"2","X"))="1",1,0),0)+IF(AND(BE7<>"",BF7<>""),IF(IF(BE7>BF7,"1",IF(BE7<BF7,"2","X"))="2",1,0),0)+IF(AND(BE8<>"",BF8<>""),IF(IF(BE8>BF8,"1",IF(BE8<BF8,"2","X"))="1",1,0),0)+IF(AND(BE9<>"",BF9<>""),IF(IF(BE9>BF9,"1",IF(BE9<BF9,"2","X"))="2",1,0),0) -> 0 | BB17: =IF(AND(BE4<>"",BF4<>""),IF(IF(BE4>BF4,"1",IF(BE4<BF4,"2","X"))="1",1,0),0)+IF(AND(BE5<>"",BF5<>""),IF(IF(BE5>BF5,"1",IF(BE5<BF5,"2","X"))="2",1,0),0)+IF(AND(BE6<>"",BF6<>""),IF(IF(BE6>BF6,"1",IF(BE6<BF6,"2","X"))="1",1,0),0)+IF(AND(BE7<>"",BF7<>""),IF(IF(BE7>BF7,"1",IF(BE7<BF7,"2","X"))="X",1,0),0)+IF(AND(BE8<>"",BF8<>""),IF(IF(BE8>BF8,"1",IF(BE8<BF8,"2","X"))="1",1,0),0)+IF(AND(BE9<>"",BF9<>""),IF(IF(BE9>BF9,"1",IF(BE9<BF9,"2","X"))="2",1,0),0) -> 0
A18: Marcadores exactos (3 pts c/u) | F18: =IF(AND(BE4<>"",BF4<>""),IF(AND(BE4=2,BF4=1),3,0),0)+IF(AND(BE5<>"",BF5<>""),IF(AND(BE5=0,BF5=2),3,0),0)+IF(AND(BE6<>"",BF6<>""),IF(AND(BE6=4,BF6=0),3,0),0)+IF(AND(BE7<>"",BF7<>""),IF(AND(BE7=0,BF7=3),3,0),0)+IF(AND(BE8<>"",BF8<>""),IF(AND(BE8=2,BF8=0),3,0),0)+IF(AND(BE9<>"",BF9<>""),IF(AND(BE9=1,BF9=4),3,0),0) -> 0 | I18: =0+0+0+0+0+0 -> 0 | L18: =IF(AND(BE4<>"",BF4<>""),IF(AND(BE4=3,BF4=1),3,0),0)+IF(AND(BE5<>"",BF5<>""),IF(AND(BE5=0,BF5=1),3,0),0)+IF(AND(BE6<>"",BF6<>""),IF(AND(BE6=5,BF6=1),3,0),0)+IF(AND(BE7<>"",BF7<>""),IF(AND(BE7=0,BF7=3),3,0),0)+IF(AND(BE8<>"",BF8<>""),IF(AND(BE8=4,BF8=0),3,0),0)+IF(AND(BE9<>"",BF9<>""),IF(AND(BE9=1,BF9=3),3,0),0) -> 0 | O18: =IF(AND(BE4<>"",BF4<>""),IF(AND(BE4=2,BF4=0),3,0),0)+IF(AND(BE5<>"",BF5<>""),IF(AND(BE5=0,BF5=2),3,0),0)+IF(AND(BE6<>"",BF6<>""),IF(AND(BE6=3,BF6=0),3,0),0)+IF(AND(BE7<>"",BF7<>""),IF(AND(BE7=1,BF7=2),3,0),0)+IF(AND(BE8<>"",BF8<>""),IF(AND(BE8=2,BF8=0),3,0),0)+IF(AND(BE9<>"",BF9<>""),IF(AND(BE9=0,BF9=2),3,0),0) -> 0 | R18: =IF(AND(BE4<>"",BF4<>""),IF(AND(BE4=2,BF4=3),3,0),0)+IF(AND(BE5<>"",BF5<>""),IF(AND(BE5=1,BF5=3),3,0),0)+IF(AND(BE6<>"",BF6<>""),IF(AND(BE6=6,BF6=1),3,0),0)+IF(AND(BE7<>"",BF7<>""),IF(AND(BE7=1,BF7=4),3,0),0)+IF(AND(BE8<>"",BF8<>""),IF(AND(BE8=5,BF8=1),3,0),0)+IF(AND(BE9<>"",BF9<>""),IF(AND(BE9=1,BF9=4),3,0),0) -> 0 | U18: =IF(AND(BE4<>"",BF4<>""),IF(AND(BE4=2,BF4=1),3,0),0)+IF(AND(BE5<>"",BF5<>""),IF(AND(BE5=0,BF5=4),3,0),0)+IF(AND(BE6<>"",BF6<>""),IF(AND(BE6=5,BF6=0),3,0),0)+IF(AND(BE7<>"",BF7<>""),IF(AND(BE7=1,BF7=2),3,0),0)+IF(AND(BE8<>"",BF8<>""),IF(AND(BE8=4,BF8=0),3,0),0)+IF(AND(BE9<>"",BF9<>""),IF(AND(BE9=1,BF9=3),3,0),0) -> 0 | X18: =IF(AND(BE4<>"",BF4<>""),IF(AND(BE4=0,BF4=1),3,0),0)+IF(AND(BE5<>"",BF5<>""),IF(AND(BE5=0,BF5=3),3,0),0)+IF(AND(BE6<>"",BF6<>""),IF(AND(BE6=5,BF6=0),3,0),0)+IF(AND(BE7<>"",BF7<>""),IF(AND(BE7=1,BF7=1),3,0),0)+IF(AND(BE8<>"",BF8<>""),IF(AND(BE8=4,BF8=0),3,0),0)+IF(AND(BE9<>"",BF9<>""),IF(AND(BE9=1,BF9=2),3,0),0) -> 0 | AA18: =IF(AND(BE4<>"",BF4<>""),IF(AND(BE4=2,BF4=0),3,0),0)+IF(AND(BE5<>"",BF5<>""),IF(AND(BE5=0,BF5=2),3,0),0)+IF(AND(BE6<>"",BF6<>""),IF(AND(BE6=4,BF6=0),3,0),0)+IF(AND(BE7<>"",BF7<>""),IF(AND(BE7=0,BF7=1),3,0),0)+IF(AND(BE8<>"",BF8<>""),IF(AND(BE8=3,BF8=0),3,0),0)+IF(AND(BE9<>"",BF9<>""),IF(AND(BE9=0,BF9=2),3,0),0) -> 0 | AD18: =IF(AND(BE4<>"",BF4<>""),IF(AND(BE4=2,BF4=2),3,0),0)+IF(AND(BE5<>"",BF5<>""),IF(AND(BE5=0,BF5=3),3,0),0)+IF(AND(BE6<>"",BF6<>""),IF(AND(BE6=2,BF6=0),3,0),0)+IF(AND(BE7<>"",BF7<>""),IF(AND(BE7=1,BF7=2),3,0),0)+IF(AND(BE8<>"",BF8<>""),IF(AND(BE8=3,BF8=0),3,0),0)+IF(AND(BE9<>"",BF9<>""),IF(AND(BE9=1,BF9=1),3,0),0) -> 0 | AG18: =IF(AND(BE4<>"",BF4<>""),IF(AND(BE4=2,BF4=1),3,0),0)+IF(AND(BE5<>"",BF5<>""),IF(AND(BE5=1,BF5=1),3,0),0)+IF(AND(BE6<>"",BF6<>""),IF(AND(BE6=3,BF6=1),3,0),0)+IF(AND(BE7<>"",BF7<>""),IF(AND(BE7=1,BF7=2),3,0),0)+IF(AND(BE8<>"",BF8<>""),IF(AND(BE8=3,BF8=0),3,0),0)+IF(AND(BE9<>"",BF9<>""),IF(AND(BE9=1,BF9=2),3,0),0) -> 0 | AJ18: =0+0+0+0+0+0 -> 0 | AM18: =IF(AND(BE4<>"",BF4<>""),IF(AND(BE4=3,BF4=1),3,0),0)+IF(AND(BE5<>"",BF5<>""),IF(AND(BE5=1,BF5=2),3,0),0)+IF(AND(BE6<>"",BF6<>""),IF(AND(BE6=3,BF6=0),3,0),0)+IF(AND(BE7<>"",BF7<>""),IF(AND(BE7=1,BF7=1),3,0),0)+IF(AND(BE8<>"",BF8<>""),IF(AND(BE8=2,BF8=1),3,0),0)+IF(AND(BE9<>"",BF9<>""),IF(AND(BE9=0,BF9=2),3,0),0) -> 0 | AP18: =IF(AND(BE4<>"",BF4<>""),IF(AND(BE4=3,BF4=1),3,0),0)+IF(AND(BE5<>"",BF5<>""),IF(AND(BE5=0,BF5=2),3,0),0)+IF(AND(BE6<>"",BF6<>""),IF(AND(BE6=4,BF6=0),3,0),0)+IF(AND(BE7<>"",BF7<>""),IF(AND(BE7=1,BF7=2),3,0),0)+IF(AND(BE8<>"",BF8<>""),IF(AND(BE8=3,BF8=0),3,0),0)+IF(AND(BE9<>"",BF9<>""),IF(AND(BE9=1,BF9=3),3,0),0) -> 0 | AS18: =IF(AND(BE4<>"",BF4<>""),IF(AND(BE4=3,BF4=1),3,0),0)+IF(AND(BE5<>"",BF5<>""),IF(AND(BE5=0,BF5=2),3,0),0)+IF(AND(BE6<>"",BF6<>""),IF(AND(BE6=4,BF6=1),3,0),0)+IF(AND(BE7<>"",BF7<>""),IF(AND(BE7=0,BF7=2),3,0),0)+IF(AND(BE8<>"",BF8<>""),IF(AND(BE8=2,BF8=0),3,0),0)+IF(AND(BE9<>"",BF9<>""),IF(AND(BE9=1,BF9=4),3,0),0) -> 0 | AV18: =IF(AND(BE4<>"",BF4<>""),IF(AND(BE4=3,BF4=1),3,0),0)+IF(AND(BE5<>"",BF5<>""),IF(AND(BE5=1,BF5=2),3,0),0)+IF(AND(BE6<>"",BF6<>""),IF(AND(BE6=4,BF6=0),3,0),0)+IF(AND(BE7<>"",BF7<>""),IF(AND(BE7=1,BF7=2),3,0),0)+IF(AND(BE8<>"",BF8<>""),IF(AND(BE8=3,BF8=0),3,0),0)+IF(AND(BE9<>"",BF9<>""),IF(AND(BE9=0,BF9=2),3,0),0) -> 0 | AY18: =IF(AND(BE4<>"",BF4<>""),IF(AND(BE4=2,BF4=2),3,0),0)+IF(AND(BE5<>"",BF5<>""),IF(AND(BE5=0,BF5=1),3,0),0)+IF(AND(BE6<>"",BF6<>""),IF(AND(BE6=3,BF6=0),3,0),0)+IF(AND(BE7<>"",BF7<>""),IF(AND(BE7=1,BF7=3),3,0),0)+IF(AND(BE8<>"",BF8<>""),IF(AND(BE8=4,BF8=0),3,0),0)+IF(AND(BE9<>"",BF9<>""),IF(AND(BE9=1,BF9=4),3,0),0) -> 0 | BB18: =IF(AND(BE4<>"",BF4<>""),IF(AND(BE4=2,BF4=1),3,0),0)+IF(AND(BE5<>"",BF5<>""),IF(AND(BE5=0,BF5=2),3,0),0)+IF(AND(BE6<>"",BF6<>""),IF(AND(BE6=4,BF6=0),3,0),0)+IF(AND(BE7<>"",BF7<>""),IF(AND(BE7=1,BF7=1),3,0),0)+IF(AND(BE8<>"",BF8<>""),IF(AND(BE8=3,BF8=0),3,0),0)+IF(AND(BE9<>"",BF9<>""),IF(AND(BE9=1,BF9=3),3,0),0) -> 0
